Workbook

Sheet Sample Info
C3: ALCHEMY Laboratory & Services Sdn. Bhd. (Company No: 903112 K) | F3: SAMM NO. 554
C4: 326B, 1st Floor, Lot 2520, Jalan Hiliran, Mukim Losong,
C5: 20300, Kuala Terengganu, Terengganu, Malaysia.
C6: Tel: +609- 622 4166, Fax: +609- 622 4177
E8: Report No : | F8: TR/BP/14798/25 - TR/BP/14823/25
E10: Date : | F10: 45976
E11: Pages : | F11: 20
C13: CERTIFICATE OF ANALYSIS
B14: Phytoplankton: Sample Information
B16: Client Name: | C16: Chemsain Konsultant Sdn. Bhd.
B17: Client Address: | C17: Lot 2, Taman Perindustrian Suria,
C18: Lorong Buah Duku 1,
C19: 88450, Kolombong,
C20: Sabah
B22: Type of Sample: | C22: Marine
B23: Sample Marking: | C23: S#
B24: Number of samples: | C24: 26
B25: Date Received: | C25: 45960
B26: Gear used: | C26: Plankton net
B27: Net diameter: | C27: 50 | D27: cm | I27: Mouth surface area: | K27: =PI()*(C27/200)^2 -> 0.19634954 | L27: m2
B28: Net mesh: | C28: 69 | D28: mm
B29: Tow type: | C29: vertical
B30: Filtered volume: | C30: (see results table)
B31: Method of Analysis: | C31: SOP No.: ALC_B_003
B32: Comments: | C32: based on APHA 10200 F
B36: The details above are provided by the client. The reported results refer to sample(s) submitted by client only.
B38: Authorized by:
B42: ……………………………………………
B43: Muhammad Firdaus Bin Daud
B44: Marine Biologist
B45: BSc.(Marine Science)

Sheet Sample List
A1: ALCHEMY Laboratory & Services Sdn Bhd
B3: Client: | C3: Chemsain Konsultant Sdn. Bhd.
B4: Institution: | C4: Chemsain Konsultant Sdn. Bhd.
B5: Description: | C5: Marine water
B7: Date Received | C7: Sample Marking | D7: Date of Analysis | E7: Reference ID | F7: Report No.
A8: 1 | B8: 45960 | C8: S1 | D8: 45973 | E8: BP14798 | F8: TR/BP/14798/25
A9: 2 | B9: 45960 | C9: S2 | D9: 45973 | E9: BP14799 | F9: TR/BP/14799/25
A10: 3 | B10: 45960 | C10: S3 | D10: 45973 | E10: BP14800 | F10: TR/BP/14800/25
A11: 4 | B11: 45960 | C11: S4 | D11: 45973 | E11: BP14801 | F11: TR/BP/14801/25
A12: 5 | B12: 45960 | C12: S5 | D12: 45973 | E12: BP14802 | F12: TR/BP/14802/25
A13: 6 | B13: 45960 | C13: S6 | D13: 45973 | E13: BP14803 | F13: TR/BP/14803/25
A14: 7 | B14: 45960 | C14: S7 | D14: 45973 | E14: BP14804 | F14: TR/BP/14804/25
A15: 8 | B15: 45960 | C15: S8 | D15: 45973 | E15: BP14805 | F15: TR/BP/14805/25
A16: 9 | B16: 45960 | C16: S9 | D16: 45973 | E16: BP14806 | F16: TR/BP/14806/25
A17: 10 | B17: 45960 | C17: S10 | D17: 45973 | E17: BP14807 | F17: TR/BP/14807/25
A18: 11 | B18: 45960 | C18: S11 | D18: 45973 | E18: BP14808 | F18: TR/BP/14808/25
A19: 12 | B19: 45960 | C19: S12 | D19: 45973 | E19: BP14809 | F19: TR/BP/14809/25
... A33: 26 | B33: 45960 | C33: S26 | D33: 45976 | E33: BP14823 | F33: TR/BP/14823/25

Sheet Phytopl Count
A1: ALCHEMY Laboratory & Services Sdn Bhd
A2: Phytoplankton Data Sheet : Raw Count Data
F3: Reference ID: | G3: BP14798 | H3: BP14799 | I3: BP14800 | J3: BP14801 | K3: BP14802 | L3: BP14803 | M3: BP14804 | N3: BP14805 | O3: BP14806 | P3: BP14807 | Q3: BP14808 | R3: BP14809 | S3: BP14810 | T3: BP14811 | U3: BP14812 | V3: BP14813 | W3: BP14814 | X3: BP14815 | Y3: BP14816 | Z3: BP14817 | AA3: BP14818 | AB3: BP14819 | AC3: BP14820 | AD3: BP14821 | AE3: BP14822 | AF3: BP14823
F4: Sample Marking: | G4: S1 | H4: S2 | I4: S3 | J4: S4 | K4: S5 | L4: S6 | M4: S7 | N4: S8 | O4: S9 | P4: S10 | Q4: S11 | R4: S12 | S4: S13 | T4: S14 | U4: S15 | V4: S16 | W4: S17 | X4: S18 | Y4: S19 | Z4: S20 | AA4: S21 | AB4: S22 | AC4: S23 | AD4: S24 | AE4: S25 | AF4: S26
F5: Date: | G5: 42701 | H5: 42701 | I5: 42701 | J5: 42701
F6: Time:
F7: Tow distance(m): | G7: 10 | H7: 10 | I7: 10 | J7: 10 | K7: 10 | L7: 10 | M7: 10 | N7: 10 | O7: 10 | P7: 10 | Q7: 10 | R7: 10 | S7: 10 | T7: 10 | U7: 10 | V7: 10 | W7: 10 | X7: 10 | Y7: 10 | Z7: 10 | AA7: 10 | AB7: 10 | AC7: 10 | AD7: 10 | AE7: 10 | AF7: 10
F8: Volume Filtered (L): | G8: ='Sample Info'!$K$27*'Phytopl Count'!G7*1000 -> 1963.4954 | H8: ='Sample Info'!$K$27*'Phytopl Count'!H7*1000 -> 1963.4954 | I8: ='Sample Info'!$K$27*'Phytopl Count'!I7*1000 -> 1963.4954 | J8: ='Sample Info'!$K$27*'Phytopl Count'!J7*1000 -> 1963.4954 | K8: ='Sample Info'!$K$27*'Phytopl Count'!K7*1000 -> 1963.4954 | L8: ='Sample Info'!$K$27*'Phytopl Count'!L7*1000 -> 1963.4954 | M8: ='Sample Info'!$K$27*'Phytopl Count'!M7*1000 -> 1963.4954 | N8: ='Sample Info'!$K$27*'Phytopl Count'!N7*1000 -> 1963.4954 | ... AF8: ='Sample Info'!$K$27*'Phytopl Count'!AF7*1000 -> 1963.4954
F9: Volume of sample(ml): | G9: 20 | H9: 30 | I9: 35 | J9: 25 | K9: 20 | L9: 15 | M9: 25 | N9: 30 | O9: 20 | P9: 20 | Q9: 25 | R9: 20 | S9: 30 | T9: 30 | U9: 20 | V9: 25 | W9: 30 | X9: 20 | Y9: 15 | Z9: 65 | AA9: 20 | AB9: 25 | AC9: 20 | AD9: 20 | AE9: 15 | AF9: 40
F10: SR cell volume(ml): | G10: 0.159 | H10: 0.159 | I10: 0.159 | J10: 0.159 | K10: 0.159 | L10: 0.159 | M10: 0.159 | N10: 0.159 | O10: 0.159 | P10: 0.159 | Q10: 0.159 | R10: 0.159 | S10: 0.159 | T10: 0.159 | U10: 0.159 | V10: 0.159 | W10: 0.159 | X10: 0.159 | Y10: 0.159 | Z10: 0.159 | AA10: 0.159 | AB10: 0.159 | AC10: 0.159 | AD10: 0.159 | AE10: 0.159 | AF10: 0.159
F11: No. SR cells counted: | G11: 3 | H11: 2 | I11: 2 | J11: 2 | K11: 2 | L11: 2 | M11: 2 | N11: 2 | O11: 2 | P11: 2 | Q11: 2 | R11: 2 | S11: 2 | T11: 2 | U11: 2 | V11: 2 | W11: 2 | X11: 2 | Y11: 2 | Z11: 2 | AA11: 2 | AB11: 2 | AC11: 2 | AD11: 2 | AE11: 2 | AF11: 2
F12: Volume counted(ml): | G12: =G10*G11 -> 0.477 | H12: =H10*H11 -> 0.318 | I12: =I10*I11 -> 0.318 | J12: =J10*J11 -> 0.318 | K12: =K10*K11 -> 0.318 | L12: =L10*L11 -> 0.318 | M12: =M10*M11 -> 0.318 | N12: =N10*N11 -> 0.318 | ... AF12: =AF10*AF11 -> 0.318
F13: Dilution factor: | G13: =IF(G8=0,"",G9/G12) -> 41.928721 | H13: =IF(H8=0,"",H9/H12) -> 94.339623 | I13: =IF(I8=0,"",I9/I12) -> 110.06289 | J13: =IF(J8=0,"",J9/J12) -> 78.616352 | K13: =IF(K8=0,"",K9/K12) -> 62.893082 | L13: =IF(L8=0,"",L9/L12) -> 47.169811 | M13: =IF(M8=0,"",M9/M12) -> 78.616352 | N13: =IF(N8=0,"",N9/N12) -> 94.339623 | ... AF13: =IF(AF8=0,"",AF9/AF12) -> 125.78616
A14: Phylum: | B14: Heterokontophyta
B15: Class: | C15: Bacillariophyceae
C16: Order: | D16: Bacillariales
D17: Family: | E17: Bacillariaceae
F18: Bacillaria
E19: Genus: | F19: Cylindrotheca | O19: 1
F20: Pseudo-nitzschia
F21: Nitzschia | G21: 29 | H21: 48 | I21: 20 | J21: 13 | K21: 22 | L21: 32 | M21: 2 | N21: 32 | O21: 26 | P21: 56 | Q21: 22 | R21: 12 | S21: 7 | T21: 118 | U21: 20 | V21: 12 | W21: 26 | X21: 14 | Y21: 3 | Z21: 232 | AA21: 10 | AB21: 10 | AC21: 28 | AD21: 69 | AE21: 3 | AF21: 2
C22: Order: | D22: Achnanthales
D23: Family: | E23: Achnanthaceae
E24: Genus: | F24: Achnanthes | Z24: 3
D25: Family: | E25: Cocconeidaceae
E26: Genus: | F26: Cocconeis
C27: Order: | D27: Fragilariales
D28: Family: | E28: Fragilariaceae
E29: Genus: | F29: Fragilaria
D30: Family: | E30: Staurosiraceae
E31: Genus: | F31: Staurosira
C32: Order: | D32: Surirellales
D33: Family: | E33: Entomoneidaceae
E34: Genus: | F34: Entomoneis
D35: Family: | E35: Surirellaceae
E36: Genus: | F36: Surirella
C37: Order: | D37: Rhabdonematales
D38: Family: | E38: Grammatophoraceae
E39: Genus: | F39: Grammatophora | H39: 23 | I39: 6 | J39: 1 | K39: 7 | L39: 19 | M39: 1 | N39: 6 | O39: 4 | P39: 56 | Q39: 7 | R39: 20 | S39: 5 | T39: 52 | U39: 2 | V39: 8 | X39: 14 | AA39: 4 | AD39: 3
C40: Order: | D40: Rhaphoneidales
...

Sheet Phytopl Analysis
A1: ALCHEMY Laboratory & Services Sdn Bhd
A2: Phytoplankton Data Sheet: Analysed Phytoplankton Samples
F3: Density in units per litre
F4: ='Phytopl Count'!F3 -> Reference ID: | G4: ='Phytopl Count'!G3 -> BP14798 | H4: ='Phytopl Count'!H3 -> BP14799 | I4: ='Phytopl Count'!I3 -> BP14800 | J4: ='Phytopl Count'!J3 -> BP14801 | K4: ='Phytopl Count'!K3 -> BP14802 | L4: ='Phytopl Count'!L3 -> BP14803 | M4: ='Phytopl Count'!M3 -> BP14804 | ... AF4: ='Phytopl Count'!AF3 -> BP14823
F5: ='Phytopl Count'!F4 -> Sample Marking: | G5: ='Phytopl Count'!G4 -> S1 | H5: ='Phytopl Count'!H4 -> S2 | I5: ='Phytopl Count'!I4 -> S3 | J5: ='Phytopl Count'!J4 -> S4 | K5: ='Phytopl Count'!K4 -> S5 | L5: ='Phytopl Count'!L4 -> S6 | M5: ='Phytopl Count'!M4 -> S7 | ... AF5: ='Phytopl Count'!AF4 -> S26
F6: Volume filtered (L): | G6: ='Phytopl Count'!G8 -> 1963.4954 | H6: ='Phytopl Count'!H8 -> 1963.4954 | I6: ='Phytopl Count'!I8 -> 1963.4954 | J6: ='Phytopl Count'!J8 -> 1963.4954 | K6: ='Phytopl Count'!K8 -> 1963.4954 | L6: ='Phytopl Count'!L8 -> 1963.4954 | M6: ='Phytopl Count'!M8 -> 1963.4954 | N6: ='Phytopl Count'!N8 -> 1963.4954 | ... AF6: ='Phytopl Count'!AF8 -> 1963.4954
A14: Phylum: | B14: Heterokontophyta | G14: =IF('Phytopl Count'!G14=0,"",'Phytopl Count'!G14*'Phytopl Count'!G$13/'Phytopl Count'!G$8) | H14: =IF('Phytopl Count'!H14=0,"",'Phytopl Count'!H14*'Phytopl Count'!H$13/'Phytopl Count'!H$8) | I14: =IF('Phytopl Count'!I14=0,"",'Phytopl Count'!I14*'Phytopl Count'!I$13/'Phytopl Count'!I$8) | J14: =IF('Phytopl Count'!J14=0,"",'Phytopl Count'!J14*'Phytopl Count'!J$13/'Phytopl Count'!J$8) | K14: =IF('Phytopl Count'!K14=0,"",'Phytopl Count'!K14*'Phytopl Count'!K$13/'Phytopl Count'!K$8) | L14: =IF('Phytopl Count'!L14=0,"",'Phytopl Count'!L14*'Phytopl Count'!L$13/'Phytopl Count'!L$8) | M14: =IF('Phytopl Count'!M14=0,"",'Phytopl Count'!M14*'Phytopl Count'!M$13/'Phytopl Count'!M$8) | N14: =IF('Phytopl Count'!N14=0,"",'Phytopl Count'!N14*'Phytopl Count'!N$13/'Phytopl Count'!N$8) | ... AF14: =IF('Phytopl Count'!AF14=0,"",'Phytopl Count'!AF14*'Phytopl Count'!AF$13/'Phytopl Count'!AF$8)
B15: Class: | C15: Bacillariophyceae | G15: =IF('Phytopl Count'!G15=0,"",'Phytopl Count'!G15*'Phytopl Count'!G$13/'Phytopl Count'!G$8) | H15: =IF('Phytopl Count'!H15=0,"",'Phytopl Count'!H15*'Phytopl Count'!H$13/'Phytopl Count'!H$8) | I15: =IF('Phytopl Count'!I15=0,"",'Phytopl Count'!I15*'Phytopl Count'!I$13/'Phytopl Count'!I$8) | J15: =IF('Phytopl Count'!J15=0,"",'Phytopl Count'!J15*'Phytopl Count'!J$13/'Phytopl Count'!J$8) | K15: =IF('Phytopl Count'!K15=0,"",'Phytopl Count'!K15*'Phytopl Count'!K$13/'Phytopl Count'!K$8) | L15: =IF('Phytopl Count'!L15=0,"",'Phytopl Count'!L15*'Phytopl Count'!L$13/'Phytopl Count'!L$8) | M15: =IF('Phytopl Count'!M15=0,"",'Phytopl Count'!M15*'Phytopl Count'!M$13/'Phytopl Count'!M$8) | N15: =IF('Phytopl Count'!N15=0,"",'Phytopl Count'!N15*'Phytopl Count'!N$13/'Phytopl Count'!N$8) | ... AF15: =IF('Phytopl Count'!AF15=0,"",'Phytopl Count'!AF15*'Phytopl Count'!AF$13/'Phytopl Count'!AF$8)
C16: Order: | D16: Bacillariales | G16: =IF('Phytopl Count'!G16=0,"",'Phytopl Count'!G16*'Phytopl Count'!G$13/'Phytopl Count'!G$8) | H16: =IF('Phytopl Count'!H16=0,"",'Phytopl Count'!H16*'Phytopl Count'!H$13/'Phytopl Count'!H$8) | I16: =IF('Phytopl Count'!I16=0,"",'Phytopl Count'!I16*'Phytopl Count'!I$13/'Phytopl Count'!I$8) | J16: =IF('Phytopl Count'!J16=0,"",'Phytopl Count'!J16*'Phytopl Count'!J$13/'Phytopl Count'!J$8) | K16: =IF('Phytopl Count'!K16=0,"",'Phytopl Count'!K16*'Phytopl Count'!K$13/'Phytopl Count'!K$8) | L16: =IF('Phytopl Count'!L16=0,"",'Phytopl Count'!L16*'Phytopl Count'!L$13/'Phytopl Count'!L$8) | M16: =IF('Phytopl Count'!M16=0,"",'Phytopl Count'!M16*'Phytopl Count'!M$13/'Phytopl Count'!M$8) | N16: =IF('Phytopl Count'!N16=0,"",'Phytopl Count'!N16*'Phytopl Count'!N$13/'Phytopl Count'!N$8) | ... AF16: =IF('Phytopl Count'!AF16=0,"",'Phytopl Count'!AF16*'Phytopl Count'!AF$13/'Phytopl Count'!AF$8)
D17: Family: | E17: Bacillariaceae | G17: =IF('Phytopl Count'!G17=0,"",'Phytopl Count'!G17*'Phytopl Count'!G$13/'Phytopl Count'!G$8) | H17: =IF('Phytopl Count'!H17=0,"",'Phytopl Count'!H17*'Phytopl Count'!H$13/'Phytopl Count'!H$8) | I17: =IF('Phytopl Count'!I17=0,"",'Phytopl Count'!I17*'Phytopl Count'!I$13/'Phytopl Count'!I$8) | J17: =IF('Phytopl Count'!J17=0,"",'Phytopl Count'!J17*'Phytopl Count'!J$13/'Phytopl Count'!J$8) | K17: =IF('Phytopl Count'!K17=0,"",'Phytopl Count'!K17*'Phytopl Count'!K$13/'Phytopl Count'!K$8) | L17: =IF('Phytopl Count'!L17=0,"",'Phytopl Count'!L17*'Phytopl Count'!L$13/'Phytopl Count'!L$8) | M17: =IF('Phytopl Count'!M17=0,"",'Phytopl Count'!M17*'Phytopl Count'!M$13/'Phytopl Count'!M$8) | N17: =IF('Phytopl Count'!N17=0,"",'Phytopl Count'!N17*'Phytopl Count'!N$13/'Phytopl Count'!N$8) | ... AF17: =IF('Phytopl Count'!AF17=0,"",'Phytopl Count'!AF17*'Phytopl Count'!AF$13/'Phytopl Count'!AF$8)
F18: Bacillaria | G18: =IF('Phytopl Count'!G18=0,"",'Phytopl Count'!G18*'Phytopl Count'!G$13/'Phytopl Count'!G$8) | H18: =IF('Phytopl Count'!H18=0,"",'Phytopl Count'!H18*'Phytopl Count'!H$13/'Phytopl Count'!H$8) | I18: =IF('Phytopl Count'!I18=0,"",'Phytopl Count'!I18*'Phytopl Count'!I$13/'Phytopl Count'!I$8) | J18: =IF('Phytopl Count'!J18=0,"",'Phytopl Count'!J18*'Phytopl Count'!J$13/'Phytopl Count'!J$8) | K18: =IF('Phytopl Count'!K18=0,"",'Phytopl Count'!K18*'Phytopl Count'!K$13/'Phytopl Count'!K$8) | L18: =IF('Phytopl Count'!L18=0,"",'Phytopl Count'!L18*'Phytopl Count'!L$13/'Phytopl Count'!L$8) | M18: =IF('Phytopl Count'!M18=0,"",'Phytopl Count'!M18*'Phytopl Count'!M$13/'Phytopl Count'!M$8) | N18: =IF('Phytopl Count'!N18=0,"",'Phytopl Count'!N18*'Phytopl Count'!N$13/'Phytopl Count'!N$8) | ... AF18: =IF('Phytopl Count'!AF18=0,"",'Phytopl Count'!AF18*'Phytopl Count'!AF$13/'Phytopl Count'!AF$8)
E19: Genus: | F19: Cylindrotheca | G19: =IF('Phytopl Count'!G19=0,"",'Phytopl Count'!G19*'Phytopl Count'!G$13/'Phytopl Count'!G$8) | H19: =IF('Phytopl Count'!H19=0,"",'Phytopl Count'!H19*'Phytopl Count'!H$13/'Phytopl Count'!H$8) | I19: =IF('Phytopl Count'!I19=0,"",'Phytopl Count'!I19*'Phytopl Count'!I$13/'Phytopl Count'!I$8) | J19: =IF('Phytopl Count'!J19=0,"",'Phytopl Count'!J19*'Phytopl Count'!J$13/'Phytopl Count'!J$8) | K19: =IF('Phytopl Count'!K19=0,"",'Phytopl Count'!K19*'Phytopl Count'!K$13/'Phytopl Count'!K$8) | L19: =IF('Phytopl Count'!L19=0,"",'Phytopl Count'!L19*'Phytopl Count'!L$13/'Phytopl Count'!L$8) | M19: =IF('Phytopl Count'!M19=0,"",'Phytopl Count'!M19*'Phytopl Count'!M$13/'Phytopl Count'!M$8) | N19: =IF('Phytopl Count'!N19=0,"",'Phytopl Count'!N19*'Phytopl Count'!N$13/'Phytopl Count'!N$8) | ... AF19: =IF('Phytopl Count'!AF19=0,"",'Phytopl Count'!AF19*'Phytopl Count'!AF$13/'Phytopl Count'!AF$8)
F20: Pseudo-nitzschia | G20: =IF('Phytopl Count'!G20=0,"",'Phytopl Count'!G20*'Phytopl Count'!G$13/'Phytopl Count'!G$8) | H20: =IF('Phytopl Count'!H20=0,"",'Phytopl Count'!H20*'Phytopl Count'!H$13/'Phytopl Count'!H$8) | I20: =IF('Phytopl Count'!I20=0,"",'Phytopl Count'!I20*'Phytopl Count'!I$13/'Phytopl Count'!I$8) | J20: =IF('Phytopl Count'!J20=0,"",'Phytopl Count'!J20*'Phytopl Count'!J$13/'Phytopl Count'!J$8) | K20: =IF('Phytopl Count'!K20=0,"",'Phytopl Count'!K20*'Phytopl Count'!K$13/'Phytopl Count'!K$8) | L20: =IF('Phytopl Count'!L20=0,"",'Phytopl Count'!L20*'Phytopl Count'!L$13/'Phytopl Count'!L$8) | M20: =IF('Phytopl Count'!M20=0,"",'Phytopl Count'!M20*'Phytopl Count'!M$13/'Phytopl Count'!M$8) | N20: =IF('Phytopl Count'!N20=0,"",'Phytopl Count'!N20*'Phytopl Count'!N$13/'Phytopl Count'!N$8) | ... AF20: =IF('Phytopl Count'!AF20=0,"",'Phytopl Count'!AF20*'Phytopl Count'!AF$13/'Phytopl Count'!AF$8)
F21: Nitzschia | G21: =IF('Phytopl Count'!G21=0,"",'Phytopl Count'!G21*'Phytopl Count'!G$13/'Phytopl Count'!G$8) -> 0.61926955 | H21: =IF('Phytopl Count'!H21=0,"",'Phytopl Count'!H21*'Phytopl Count'!H$13/'Phytopl Count'!H$8) -> 2.3062452 | I21: =IF('Phytopl Count'!I21=0,"",'Phytopl Count'!I21*'Phytopl Count'!I$13/'Phytopl Count'!I$8) -> 1.1210914 | J21: =IF('Phytopl Count'!J21=0,"",'Phytopl Count'!J21*'Phytopl Count'!J$13/'Phytopl Count'!J$8) -> 0.52050673 | K21: =IF('Phytopl Count'!K21=0,"",'Phytopl Count'!K21*'Phytopl Count'!K$13/'Phytopl Count'!K$8) -> 0.70468604 | L21: =IF('Phytopl Count'!L21=0,"",'Phytopl Count'!L21*'Phytopl Count'!L$13/'Phytopl Count'!L$8) -> 0.7687484 | M21: =IF('Phytopl Count'!M21=0,"",'Phytopl Count'!M21*'Phytopl Count'!M$13/'Phytopl Count'!M$8) -> 0.080077959 | N21: =IF('Phytopl Count'!N21=0,"",'Phytopl Count'!N21*'Phytopl Count'!N$13/'Phytopl Count'!N$8) -> 1.5374968 | ... AF21: =IF('Phytopl Count'!AF21=0,"",'Phytopl Count'!AF21*'Phytopl Count'!AF$13/'Phytopl Count'!AF$8) -> 0.12812473
C22: Order: | D22: Achnanthales | G22: =IF('Phytopl Count'!G22=0,"",'Phytopl Count'!G22*'Phytopl Count'!G$13/'Phytopl Count'!G$8) | H22: =IF('Phytopl Count'!H22=0,"",'Phytopl Count'!H22*'Phytopl Count'!H$13/'Phytopl Count'!H$8) | I22: =IF('Phytopl Count'!I22=0,"",'Phytopl Count'!I22*'Phytopl Count'!I$13/'Phytopl Count'!I$8) | J22: =IF('Phytopl Count'!J22=0,"",'Phytopl Count'!J22*'Phytopl Count'!J$13/'Phytopl Count'!J$8) | K22: =IF('Phytopl Count'!K22=0,"",'Phytopl Count'!K22*'Phytopl Count'!K$13/'Phytopl Count'!K$8) | L22: =IF('Phytopl Count'!L22=0,"",'Phytopl Count'!L22*'Phytopl Count'!L$13/'Phytopl Count'!L$8) | M22: =IF('Phytopl Count'!M22=0,"",'Phytopl Count'!M22*'Phytopl Count'!M$13/'Phytopl Count'!M$8) | N22: =IF('Phytopl Count'!N22=0,"",'Phytopl Count'!N22*'Phytopl Count'!N$13/'Phytopl Count'!N$8) | ... AF22: =IF('Phytopl Count'!AF22=0,"",'Phytopl Count'!AF22*'Phytopl Count'!AF$13/'Phytopl Count'!AF$8)
D23: Family: | E23: Achnanthaceae | G23: =IF('Phytopl Count'!G23=0,"",'Phytopl Count'!G23*'Phytopl Count'!G$13/'Phytopl Count'!G$8) | H23: =IF('Phytopl Count'!H23=0,"",'Phytopl Count'!H23*'Phytopl Count'!H$13/'Phytopl Count'!H$8) | I23: =IF('Phytopl Count'!I23=0,"",'Phytopl Count'!I23*'Phytopl Count'!I$13/'Phytopl Count'!I$8) | J23: =IF('Phytopl Count'!J23=0,"",'Phytopl Count'!J23*'Phytopl Count'!J$13/'Phytopl Count'!J$8) | K23: =IF('Phytopl Count'!K23=0,"",'Phytopl Count'!K23*'Phytopl Count'!K$13/'Phytopl Count'!K$8) | L23: =IF('Phytopl Count'!L23=0,"",'Phytopl Count'!L23*'Phytopl Count'!L$13/'Phytopl Count'!L$8) | M23: =IF('Phytopl Count'!M23=0,"",'Phytopl Count'!M23*'Phytopl Count'!M$13/'Phytopl Count'!M$8) | N23: =IF('Phytopl Count'!N23=0,"",'Phytopl Count'!N23*'Phytopl Count'!N$13/'Phytopl Count'!N$8) | ... AF23: =IF('Phytopl Count'!AF23=0,"",'Phytopl Count'!AF23*'Phytopl Count'!AF$13/'Phytopl Count'!AF$8)
E24: Genus: | F24: Achnanthes | G24: =IF('Phytopl Count'!G24=0,"",'Phytopl Count'!G24*'Phytopl Count'!G$13/'Phytopl Count'!G$8) | H24: =IF('Phytopl Count'!H24=0,"",'Phytopl Count'!H24*'Phytopl Count'!H$13/'Phytopl Count'!H$8) | I24: =IF('Phytopl Count'!I24=0,"",'Phytopl Count'!I24*'Phytopl Count'!I$13/'Phytopl Count'!I$8) | J24: =IF('Phytopl Count'!J24=0,"",'Phytopl Count'!J24*'Phytopl Count'!J$13/'Phytopl Count'!J$8) | K24: =IF('Phytopl Count'!K24=0,"",'Phytopl Count'!K24*'Phytopl Count'!K$13/'Phytopl Count'!K$8) | L24: =IF('Phytopl Count'!L24=0,"",'Phytopl Count'!L24*'Phytopl Count'!L$13/'Phytopl Count'!L$8) | M24: =IF('Phytopl Count'!M24=0,"",'Phytopl Count'!M24*'Phytopl Count'!M$13/'Phytopl Count'!M$8) | N24: =IF('Phytopl Count'!N24=0,"",'Phytopl Count'!N24*'Phytopl Count'!N$13/'Phytopl Count'!N$8) | ... AF24: =IF('Phytopl Count'!AF24=0,"",'Phytopl Count'!AF24*'Phytopl Count'!AF$13/'Phytopl Count'!AF$8)
D25: Family: | E25: Cocconeidaceae | G25: =IF('Phytopl Count'!G25=0,"",'Phytopl Count'!G25*'Phytopl Count'!G$13/'Phytopl Count'!G$8) | H25: =IF('Phytopl Count'!H25=0,"",'Phytopl Count'!H25*'Phytopl Count'!H$13/'Phytopl Count'!H$8) | I25: =IF('Phytopl Count'!I25=0,"",'Phytopl Count'!I25*'Phytopl Count'!I$13/'Phytopl Count'!I$8) | J25: =IF('Phytopl Count'!J25=0,"",'Phytopl Count'!J25*'Phytopl Count'!J$13/'Phytopl Count'!J$8) | K25: =IF('Phytopl Count'!K25=0,"",'Phytopl Count'!K25*'Phytopl Count'!K$13/'Phytopl Count'!K$8) | L25: =IF('Phytopl Count'!L25=0,"",'Phytopl Count'!L25*'Phytopl Count'!L$13/'Phytopl Count'!L$8) | M25: =IF('Phytopl Count'!M25=0,"",'Phytopl Count'!M25*'Phytopl Count'!M$13/'Phytopl Count'!M$8) | N25: =IF('Phytopl Count'!N25=0,"",'Phytopl Count'!N25*'Phytopl Count'!N$13/'Phytopl Count'!N$8) | ... AF25: =IF('Phytopl Count'!AF25=0,"",'Phytopl Count'!AF25*'Phytopl Count'!AF$13/'Phytopl Count'!AF$8)
E26: Genus: | F26: Cocconeis | G26: =IF('Phytopl Count'!G26=0,"",'Phytopl Count'!G26*'Phytopl Count'!G$13/'Phytopl Count'!G$8) | H26: =IF('Phytopl Count'!H26=0,"",'Phytopl Count'!H26*'Phytopl Count'!H$13/'Phytopl Count'!H$8) | I26: =IF('Phytopl Count'!I26=0,"",'Phytopl Count'!I26*'Phytopl Count'!I$13/'Phytopl Count'!I$8) | J26: =IF('Phytopl Count'!J26=0,"",'Phytopl Count'!J26*'Phytopl Count'!J$13/'Phytopl Count'!J$8) | K26: =IF('Phytopl Count'!K26=0,"",'Phytopl Count'!K26*'Phytopl Count'!K$13/'Phytopl Count'!K$8) | L26: =IF('Phytopl Count'!L26=0,"",'Phytopl Count'!L26*'Phytopl Count'!L$13/'Phytopl Count'!L$8) | M26: =IF('Phytopl Count'!M26=0,"",'Phytopl Count'!M26*'Phytopl Count'!M$13/'Phytopl Count'!M$8) | N26: =IF('Phytopl Count'!N26=0,"",'Phytopl Count'!N26*'Phytopl Count'!N$13/'Phytopl Count'!N$8) | ... AF26: =IF('Phytopl Count'!AF26=0,"",'Phytopl Count'!AF26*'Phytopl Count'!AF$13/'Phytopl Count'!AF$8)
C27: Order: | D27: Fragilariales | G27: =IF('Phytopl Count'!G27=0,"",'Phytopl Count'!G27*'Phytopl Count'!G$13/'Phytopl Count'!G$8) | H27: =IF('Phytopl Count'!H27=0,"",'Phytopl Count'!H27*'Phytopl Count'!H$13/'Phytopl Count'!H$8) | I27: =IF('Phytopl Count'!I27=0,"",'Phytopl Count'!I27*'Phytopl Count'!I$13/'Phytopl Count'!I$8) | J27: =IF('Phytopl Count'!J27=0,"",'Phytopl Count'!J27*'Phytopl Count'!J$13/'Phytopl Count'!J$8) | K27: =IF('Phytopl Count'!K27=0,"",'Phytopl Count'!K27*'Phytopl Count'!K$13/'Phytopl Count'!K$8) | L27: =IF('Phytopl Count'!L27=0,"",'Phytopl Count'!L27*'Phytopl Count'!L$13/'Phytopl Count'!L$8) | M27: =IF('Phytopl Count'!M27=0,"",'Phytopl Count'!M27*'Phytopl Count'!M$13/'Phytopl Count'!M$8) | N27: =IF('Phytopl Count'!N27=0,"",'Phytopl Count'!N27*'Phytopl Count'!N$13/'Phytopl Count'!N$8) | ... AF27: =IF('Phytopl Count'!AF27=0,"",'Phytopl Count'!AF27*'Phytopl Count'!AF$13/'Phytopl Count'!AF$8)
D28: Family: | E28: Fragilariaceae | G28: =IF('Phytopl Count'!G28=0,"",'Phytopl Count'!G28*'Phytopl Count'!G$13/'Phytopl Count'!G$8) | H28: =IF('Phytopl Count'!H28=0,"",'Phytopl Count'!H28*'Phytopl Count'!H$13/'Phytopl Count'!H$8) | I28: =IF('Phytopl Count'!I28=0,"",'Phytopl Count'!I28*'Phytopl Count'!I$13/'Phytopl Count'!I$8) | J28: =IF('Phytopl Count'!J28=0,"",'Phytopl Count'!J28*'Phytopl Count'!J$13/'Phytopl Count'!J$8) | K28: =IF('Phytopl Count'!K28=0,"",'Phytopl Count'!K28*'Phytopl Count'!K$13/'Phytopl Count'!K$8) | L28: =IF('Phytopl Count'!L28=0,"",'Phytopl Count'!L28*'Phytopl Count'!L$13/'Phytopl Count'!L$8) | M28: =IF('Phytopl Count'!M28=0,"",'Phytopl Count'!M28*'Phytopl Count'!M$13/'Phytopl Count'!M$8) | N28: =IF('Phytopl Count'!N28=0,"",'Phytopl Count'!N28*'Phytopl Count'!N$13/'Phytopl Count'!N$8) | ... AF28: =IF('Phytopl Count'!AF28=0,"",'Phytopl Count'!AF28*'Phytopl Count'!AF$13/'Phytopl Count'!AF$8)
E29: Genus: | F29: Fragilaria | G29: =IF('Phytopl Count'!G29=0,"",'Phytopl Count'!G29*'Phytopl Count'!G$13/'Phytopl Count'!G$8) | H29: =IF('Phytopl Count'!H29=0,"",'Phytopl Count'!H29*'Phytopl Count'!H$13/'Phytopl Count'!H$8) | I29: =IF('Phytopl Count'!I29=0,"",'Phytopl Count'!I29*'Phytopl Count'!I$13/'Phytopl Count'!I$8) | J29: =IF('Phytopl Count'!J29=0,"",'Phytopl Count'!J29*'Phytopl Count'!J$13/'Phytopl Count'!J$8) | K29: =IF('Phytopl Count'!K29=0,"",'Phytopl Count'!K29*'Phytopl Count'!K$13/'Phytopl Count'!K$8) | L29: =IF('Phytopl Count'!L29=0,"",'Phytopl Count'!L29*'Phytopl Count'!L$13/'Phytopl Count'!L$8) | M29: =IF('Phytopl Count'!M29=0,"",'Phytopl Count'!M29*'Phytopl Count'!M$13/'Phytopl Count'!M$8) | N29: =IF('Phytopl Count'!N29=0,"",'Phytopl Count'!N29*'Phytopl Count'!N$13/'Phytopl Count'!N$8) | ... AF29: =IF('Phytopl Count'!AF29=0,"",'Phytopl Count'!AF29*'Phytopl Count'!AF$13/'Phytopl Count'!AF$8)
D30: Family: | E30: Staurosiraceae | G30: =IF('Phytopl Count'!G30=0,"",'Phytopl Count'!G30*'Phytopl Count'!G$13/'Phytopl Count'!G$8) | H30: =IF('Phytopl Count'!H30=0,"",'Phytopl Count'!H30*'Phytopl Count'!H$13/'Phytopl Count'!H$8) | I30: =IF('Phytopl Count'!I30=0,"",'Phytopl Count'!I30*'Phytopl Count'!I$13/'Phytopl Count'!I$8) | J30: =IF('Phytopl Count'!J30=0,"",'Phytopl Count'!J30*'Phytopl Count'!J$13/'Phytopl Count'!J$8) | K30: =IF('Phytopl Count'!K30=0,"",'Phytopl Count'!K30*'Phytopl Count'!K$13/'Phytopl Count'!K$8) | L30: =IF('Phytopl Count'!L30=0,"",'Phytopl Count'!L30*'Phytopl Count'!L$13/'Phytopl Count'!L$8) | M30: =IF('Phytopl Count'!M30=0,"",'Phytopl Count'!M30*'Phytopl Count'!M$13/'Phytopl Count'!M$8) | N30: =IF('Phytopl Count'!N30=0,"",'Phytopl Count'!N30*'Phytopl Count'!N$13/'Phytopl Count'!N$8) | ... AF30: =IF('Phytopl Count'!AF30=0,"",'Phytopl Count'!AF30*'Phytopl Count'!AF$13/'Phytopl Count'!AF$8)
E31: Genus: | F31: Staurosira | G31: =IF('Phytopl Count'!G31=0,"",'Phytopl Count'!G31*'Phytopl Count'!G$13/'Phytopl Count'!G$8) | H31: =IF('Phytopl Count'!H31=0,"",'Phytopl Count'!H31*'Phytopl Count'!H$13/'Phytopl Count'!H$8) | I31: =IF('Phytopl Count'!I31=0,"",'Phytopl Count'!I31*'Phytopl Count'!I$13/'Phytopl Count'!I$8) | J31: =IF('Phytopl Count'!J31=0,"",'Phytopl Count'!J31*'Phytopl Count'!J$13/'Phytopl Count'!J$8) | K31: =IF('Phytopl Count'!K31=0,"",'Phytopl Count'!K31*'Phytopl Count'!K$13/'Phytopl Count'!K$8) | L31: =IF('Phytopl Count'!L31=0,"",'Phytopl Count'!L31*'Phytopl Count'!L$13/'Phytopl Count'!L$8) | M31: =IF('Phytopl Count'!M31=0,"",'Phytopl Count'!M31*'Phytopl Count'!M$13/'Phytopl Count'!M$8) | N31: =IF('Phytopl Count'!N31=0,"",'Phytopl Count'!N31*'Phytopl Count'!N$13/'Phytopl Count'!N$8) | ... AF31: =IF('Phytopl Count'!AF31=0,"",'Phytopl Count'!AF31*'Phytopl Count'!AF$13/'Phytopl Count'!AF$8)
C32: Order: | D32: Surirellales | G32: =IF('Phytopl Count'!G32=0,"",'Phytopl Count'!G32*'Phytopl Count'!G$13/'Phytopl Count'!G$8) | H32: =IF('Phytopl Count'!H32=0,"",'Phytopl Count'!H32*'Phytopl Count'!H$13/'Phytopl Count'!H$8) | I32: =IF('Phytopl Count'!I32=0,"",'Phytopl Count'!I32*'Phytopl Count'!I$13/'Phytopl Count'!I$8) | J32: =IF('Phytopl Count'!J32=0,"",'Phytopl Count'!J32*'Phytopl Count'!J$13/'Phytopl Count'!J$8) | K32: =IF('Phytopl Count'!K32=0,"",'Phytopl Count'!K32*'Phytopl Count'!K$13/'Phytopl Count'!K$8) | L32: =IF('Phytopl Count'!L32=0,"",'Phytopl Count'!L32*'Phytopl Count'!L$13/'Phytopl Count'!L$8) | M32: =IF('Phytopl Count'!M32=0,"",'Phytopl Count'!M32*'Phytopl Count'!M$13/'Phytopl Count'!M$8) | N32: =IF('Phytopl Count'!N32=0,"",'Phytopl Count'!N32*'Phytopl Count'!N$13/'Phytopl Count'!N$8) | ... AF32: =IF('Phytopl Count'!AF32=0,"",'Phytopl Count'!AF32*'Phytopl Count'!AF$13/'Phytopl Count'!AF$8)
D33: Family: | E33: Entomoneidaceae | G33: =IF('Phytopl Count'!G33=0,"",'Phytopl Count'!G33*'Phytopl Count'!G$13/'Phytopl Count'!G$8) | H33: =IF('Phytopl Count'!H33=0,"",'Phytopl Count'!H33*'Phytopl Count'!H$13/'Phytopl Count'!H$8) | I33: =IF('Phytopl Count'!I33=0,"",'Phytopl Count'!I33*'Phytopl Count'!I$13/'Phytopl Count'!I$8) | J33: =IF('Phytopl Count'!J33=0,"",'Phytopl Count'!J33*'Phytopl Count'!J$13/'Phytopl Count'!J$8) | K33: =IF('Phytopl Count'!K33=0,"",'Phytopl Count'!K33*'Phytopl Count'!K$13/'Phytopl Count'!K$8) | L33: =IF('Phytopl Count'!L33=0,"",'Phytopl Count'!L33*'Phytopl Count'!L$13/'Phytopl Count'!L$8) | M33: =IF('Phytopl Count'!M33=0,"",'Phytopl Count'!M33*'Phytopl Count'!M$13/'Phytopl Count'!M$8) | N33: =IF('Phytopl Count'!N33=0,"",'Phytopl Count'!N33*'Phytopl Count'!N$13/'Phytopl Count'!N$8) | ... AF33: =IF('Phytopl Count'!AF33=0,"",'Phytopl Count'!AF33*'Phytopl Count'!AF$13/'Phytopl Count'!AF$8)
E34: Genus: | F34: Entomoneis | G34: =IF('Phytopl Count'!G34=0,"",'Phytopl Count'!G34*'Phytopl Count'!G$13/'Phytopl Count'!G$8) | H34: =IF('Phytopl Count'!H34=0,"",'Phytopl Count'!H34*'Phytopl Count'!H$13/'Phytopl Count'!H$8) | I34: =IF('Phytopl Count'!I34=0,"",'Phytopl Count'!I34*'Phytopl Count'!I$13/'Phytopl Count'!I$8) | J34: =IF('Phytopl Count'!J34=0,"",'Phytopl Count'!J34*'Phytopl Count'!J$13/'Phytopl Count'!J$8) | K34: =IF('Phytopl Count'!K34=0,"",'Phytopl Count'!K34*'Phytopl Count'!K$13/'Phytopl Count'!K$8) | L34: =IF('Phytopl Count'!L34=0,"",'Phytopl Count'!L34*'Phytopl Count'!L$13/'Phytopl Count'!L$8) | M34: =IF('Phytopl Count'!M34=0,"",'Phytopl Count'!M34*'Phytopl Count'!M$13/'Phytopl Count'!M$8) | N34: =IF('Phytopl Count'!N34=0,"",'Phytopl Count'!N34*'Phytopl Count'!N$13/'Phytopl Count'!N$8) | ... AF34: =IF('Phytopl Count'!AF34=0,"",'Phytopl Count'!AF34*'Phytopl Count'!AF$13/'Phytopl Count'!AF$8)
D35: Family: | E35: Surirellaceae | G35: =IF('Phytopl Count'!G35=0,"",'Phytopl Count'!G35*'Phytopl Count'!G$13/'Phytopl Count'!G$8) | H35: =IF('Phytopl Count'!H35=0,"",'Phytopl Count'!H35*'Phytopl Count'!H$13/'Phytopl Count'!H$8) | I35: =IF('Phytopl Count'!I35=0,"",'Phytopl Count'!I35*'Phytopl Count'!I$13/'Phytopl Count'!I$8) | J35: =IF('Phytopl Count'!J35=0,"",'Phytopl Count'!J35*'Phytopl Count'!J$13/'Phytopl Count'!J$8) | K35: =IF('Phytopl Count'!K35=0,"",'Phytopl Count'!K35*'Phytopl Count'!K$13/'Phytopl Count'!K$8) | L35: =IF('Phytopl Count'!L35=0,"",'Phytopl Count'!L35*'Phytopl Count'!L$13/'Phytopl Count'!L$8) | M35: =IF('Phytopl Count'!M35=0,"",'Phytopl Count'!M35*'Phytopl Count'!M$13/'Phytopl Count'!M$8) | N35: =IF('Phytopl Count'!N35=0,"",'Phytopl Count'!N35*'Phytopl Count'!N$13/'Phytopl Count'!N$8) | ... AF35: =IF('Phytopl Count'!AF35=0,"",'Phytopl Count'!AF35*'Phytopl Count'!AF$13/'Phytopl Count'!AF$8)
E36: Genus: | F36: Surirella | G36: =IF('Phytopl Count'!G36=0,"",'Phytopl Count'!G36*'Phytopl Count'!G$13/'Phytopl Count'!G$8) | H36: =IF('Phytopl Count'!H36=0,"",'Phytopl Count'!H36*'Phytopl Count'!H$13/'Phytopl Count'!H$8) | I36: =IF('Phytopl Count'!I36=0,"",'Phytopl Count'!I36*'Phytopl Count'!I$13/'Phytopl Count'!I$8) | J36: =IF('Phytopl Count'!J36=0,"",'Phytopl Count'!J36*'Phytopl Count'!J$13/'Phytopl Count'!J$8) | K36: =IF('Phytopl Count'!K36=0,"",'Phytopl Count'!K36*'Phytopl Count'!K$13/'Phytopl Count'!K$8) | L36: =IF('Phytopl Count'!L36=0,"",'Phytopl Count'!L36*'Phytopl Count'!L$13/'Phytopl Count'!L$8) | M36: =IF('Phytopl Count'!M36=0,"",'Phytopl Count'!M36*'Phytopl Count'!M$13/'Phytopl Count'!M$8) | N36: =IF('Phytopl Count'!N36=0,"",'Phytopl Count'!N36*'Phytopl Count'!N$13/'Phytopl Count'!N$8) | ... AF36: =IF('Phytopl Count'!AF36=0,"",'Phytopl Count'!AF36*'Phytopl Count'!AF$13/'Phytopl Count'!AF$8)
C37: Order: | D37: Rhabdonematales | G37: =IF('Phytopl Count'!G37=0,"",'Phytopl Count'!G37*'Phytopl Count'!G$13/'Phytopl Count'!G$8) | H37: =IF('Phytopl Count'!H37=0,"",'Phytopl Count'!H37*'Phytopl Count'!H$13/'Phytopl Count'!H$8) | I37: =IF('Phytopl Count'!I37=0,"",'Phytopl Count'!I37*'Phytopl Count'!I$13/'Phytopl Count'!I$8) | J37: =IF('Phytopl Count'!J37=0,"",'Phytopl Count'!J37*'Phytopl Count'!J$13/'Phytopl Count'!J$8) | K37: =IF('Phytopl Count'!K37=0,"",'Phytopl Count'!K37*'Phytopl Count'!K$13/'Phytopl Count'!K$8) | L37: =IF('Phytopl Count'!L37=0,"",'Phytopl Count'!L37*'Phytopl Count'!L$13/'Phytopl Count'!L$8) | M37: =IF('Phytopl Count'!M37=0,"",'Phytopl Count'!M37*'Phytopl Count'!M$13/'Phytopl Count'!M$8) | N37: =IF('Phytopl Count'!N37=0,"",'Phytopl Count'!N37*'Phytopl Count'!N$13/'Phytopl Count'!N$8) | ... AF37: =IF('Phytopl Count'!AF37=0,"",'Phytopl Count'!AF37*'Phytopl Count'!AF$13/'Phytopl Count'!AF$8)
D38: Family: | E38: Grammatophoraceae | G38: =IF('Phytopl Count'!G38=0,"",'Phytopl Count'!G38*'Phytopl Count'!G$13/'Phytopl Count'!G$8) | H38: =IF('Phytopl Count'!H38=0,"",'Phytopl Count'!H38*'Phytopl Count'!H$13/'Phytopl Count'!H$8) | I38: =IF('Phytopl Count'!I38=0,"",'Phytopl Count'!I38*'Phytopl Count'!I$13/'Phytopl Count'!I$8) | J38: =IF('Phytopl Count'!J38=0,"",'Phytopl Count'!J38*'Phytopl Count'!J$13/'Phytopl Count'!J$8) | K38: =IF('Phytopl Count'!K38=0,"",'Phytopl Count'!K38*'Phytopl Count'!K$13/'Phytopl Count'!K$8) | L38: =IF('Phytopl Count'!L38=0,"",'Phytopl Count'!L38*'Phytopl Count'!L$13/'Phytopl Count'!L$8) | M38: =IF('Phytopl Count'!M38=0,"",'Phytopl Count'!M38*'Phytopl Count'!M$13/'Phytopl Count'!M$8) | N38: =IF('Phytopl Count'!N38=0,"",'Phytopl Count'!N38*'Phytopl Count'!N$13/'Phytopl Count'!N$8) | ... AF38: =IF('Phytopl Count'!AF38=0,"",'Phytopl Count'!AF38*'Phytopl Count'!AF$13/'Phytopl Count'!AF$8)
E39: Genus: | F39: Grammatophora | G39: =IF('Phytopl Count'!G39=0,"",'Phytopl Count'!G39*'Phytopl Count'!G$13/'Phytopl Count'!G$8) | H39: =IF('Phytopl Count'!H39=0,"",'Phytopl Count'!H39*'Phytopl Count'!H$13/'Phytopl Count'!H$8) -> 1.1050758 | I39: =IF('Phytopl Count'!I39=0,"",'Phytopl Count'!I39*'Phytopl Count'!I$13/'Phytopl Count'!I$8) -> 0.33632743 | J39: =IF('Phytopl Count'!J39=0,"",'Phytopl Count'!J39*'Phytopl Count'!J$13/'Phytopl Count'!J$8) -> 0.040038979 | K39: =IF('Phytopl Count'!K39=0,"",'Phytopl Count'!K39*'Phytopl Count'!K$13/'Phytopl Count'!K$8) -> 0.22421828 | L39: =IF('Phytopl Count'!L39=0,"",'Phytopl Count'!L39*'Phytopl Count'!L$13/'Phytopl Count'!L$8) -> 0.45644437 | M39: =IF('Phytopl Count'!M39=0,"",'Phytopl Count'!M39*'Phytopl Count'!M$13/'Phytopl Count'!M$8) -> 0.040038979 | N39: =IF('Phytopl Count'!N39=0,"",'Phytopl Count'!N39*'Phytopl Count'!N$13/'Phytopl Count'!N$8) -> 0.28828065 | ... AF39: =IF('Phytopl Count'!AF39=0,"",'Phytopl Count'!AF39*'Phytopl Count'!AF$13/'Phytopl Count'!AF$8)
C40: Order: | D40: Rhaphoneidales | G40: =IF('Phytopl Count'!G40=0,"",'Phytopl Count'!G40*'Phytopl Count'!G$13/'Phytopl Count'!G$8) | H40: =IF('Phytopl Count'!H40=0,"",'Phytopl Count'!H40*'Phytopl Count'!H$13/'Phytopl Count'!H$8) | I40: =IF('Phytopl Count'!I40=0,"",'Phytopl Count'!I40*'Phytopl Count'!I$13/'Phytopl Count'!I$8) | J40: =IF('Phytopl Count'!J40=0,"",'Phytopl Count'!J40*'Phytopl Count'!J$13/'Phytopl Count'!J$8) | K40: =IF('Phytopl Count'!K40=0,"",'Phytopl Count'!K40*'Phytopl Count'!K$13/'Phytopl Count'!K$8) | L40: =IF('Phytopl Count'!L40=0,"",'Phytopl Count'!L40*'Phytopl Count'!L$13/'Phytopl Count'!L$8) | M40: =IF('Phytopl Count'!M40=0,"",'Phytopl Count'!M40*'Phytopl Count'!M$13/'Phytopl Count'!M$8) | N40: =IF('Phytopl Count'!N40=0,"",'Phytopl Count'!N40*'Phytopl Count'!N$13/'Phytopl Count'!N$8) | ... AF40: =IF('Phytopl Count'!AF40=0,"",'Phytopl Count'!AF40*'Phytopl Count'!AF$13/'Phytopl Count'!AF$8)
D41: Family: | E41: Asterionellopsidaceae | G41: =IF('Phytopl Count'!G41=0,"",'Phytopl Count'!G41*'Phytopl Count'!G$13/'Phytopl Count'!G$8) | H41: =IF('Phytopl Count'!H41=0,"",'Phytopl Count'!H41*'Phytopl Count'!H$13/'Phytopl Count'!H$8) | I41: =IF('Phytopl Count'!I41=0,"",'Phytopl Count'!I41*'Phytopl Count'!I$13/'Phytopl Count'!I$8) | J41: =IF('Phytopl Count'!J41=0,"",'Phytopl Count'!J41*'Phytopl Count'!J$13/'Phytopl Count'!J$8) | K41: =IF('Phytopl Count'!K41=0,"",'Phytopl Count'!K41*'Phytopl Count'!K$13/'Phytopl Count'!K$8) | L41: =IF('Phytopl Count'!L41=0,"",'Phytopl Count'!L41*'Phytopl Count'!L$13/'Phytopl Count'!L$8) | M41: =IF('Phytopl Count'!M41=0,"",'Phytopl Count'!M41*'Phytopl Count'!M$13/'Phytopl Count'!M$8) | N41: =IF('Phytopl Count'!N41=0,"",'Phytopl Count'!N41*'Phytopl Count'!N$13/'Phytopl Count'!N$8) | ... AF41: =IF('Phytopl Count'!AF41=0,"",'Phytopl Count'!AF41*'Phytopl Count'!AF$13/'Phytopl Count'!AF$8)
E42: Genus: | F42: Asterionellopsis | G42: =IF('Phytopl Count'!G42=0,"",'Phytopl Count'!G42*'Phytopl Count'!G$13/'Phytopl Count'!G$8) | H42: =IF('Phytopl Count'!H42=0,"",'Phytopl Count'!H42*'Phytopl Count'!H$13/'Phytopl Count'!H$8) | I42: =IF('Phytopl Count'!I42=0,"",'Phytopl Count'!I42*'Phytopl Count'!I$13/'Phytopl Count'!I$8) | J42: =IF('Phytopl Count'!J42=0,"",'Phytopl Count'!J42*'Phytopl Count'!J$13/'Phytopl Count'!J$8) | K42: =IF('Phytopl Count'!K42=0,"",'Phytopl Count'!K42*'Phytopl Count'!K$13/'Phytopl Count'!K$8) | L42: =IF('Phytopl Count'!L42=0,"",'Phytopl Count'!L42*'Phytopl Count'!L$13/'Phytopl Count'!L$8) | M42: =IF('Phytopl Count'!M42=0,"",'Phytopl Count'!M42*'Phytopl Count'!M$13/'Phytopl Count'!M$8) | N42: =IF('Phytopl Count'!N42=0,"",'Phytopl Count'!N42*'Phytopl Count'!N$13/'Phytopl Count'!N$8) | ... AF42: =IF('Phytopl Count'!AF42=0,"",'Phytopl Count'!AF42*'Phytopl Count'!AF$13/'Phytopl Count'!AF$8)
D43: Family: | E43: Tabellariaceae | G43: =IF('Phytopl Count'!G43=0,"",'Phytopl Count'!G43*'Phytopl Count'!G$13/'Phytopl Count'!G$8) | H43: =IF('Phytopl Count'!H43=0,"",'Phytopl Count'!H43*'Phytopl Count'!H$13/'Phytopl Count'!H$8) | I43: =IF('Phytopl Count'!I43=0,"",'Phytopl Count'!I43*'Phytopl Count'!I$13/'Phytopl Count'!I$8) | J43: =IF('Phytopl Count'!J43=0,"",'Phytopl Count'!J43*'Phytopl Count'!J$13/'Phytopl Count'!J$8) | K43: =IF('Phytopl Count'!K43=0,"",'Phytopl Count'!K43*'Phytopl Count'!K$13/'Phytopl Count'!K$8) | L43: =IF('Phytopl Count'!L43=0,"",'Phytopl Count'!L43*'Phytopl Count'!L$13/'Phytopl Count'!L$8) | M43: =IF('Phytopl Count'!M43=0,"",'Phytopl Count'!M43*'Phytopl Count'!M$13/'Phytopl Count'!M$8) | N43: =IF('Phytopl Count'!N43=0,"",'Phytopl Count'!N43*'Phytopl Count'!N$13/'Phytopl Count'!N$8) | ... AF43: =IF('Phytopl Count'!AF43=0,"",'Phytopl Count'!AF43*'Phytopl Count'!AF$13/'Phytopl Count'!AF$8)
E44: Genus: | F44: Asterionella | G44: =IF('Phytopl Count'!G44=0,"",'Phytopl Count'!G44*'Phytopl Count'!G$13/'Phytopl Count'!G$8) | H44: =IF('Phytopl Count'!H44=0,"",'Phytopl Count'!H44*'Phytopl Count'!H$13/'Phytopl Count'!H$8) | I44: =IF('Phytopl Count'!I44=0,"",'Phytopl Count'!I44*'Phytopl Count'!I$13/'Phytopl Count'!I$8) | J44: =IF('Phytopl Count'!J44=0,"",'Phytopl Count'!J44*'Phytopl Count'!J$13/'Phytopl Count'!J$8) | K44: =IF('Phytopl Count'!K44=0,"",'Phytopl Count'!K44*'Phytopl Count'!K$13/'Phytopl Count'!K$8) | L44: =IF('Phytopl Count'!L44=0,"",'Phytopl Count'!L44*'Phytopl Count'!L$13/'Phytopl Count'!L$8) | M44: =IF('Phytopl Count'!M44=0,"",'Phytopl Count'!M44*'Phytopl Count'!M$13/'Phytopl Count'!M$8) | N44: =IF('Phytopl Count'!N44=0,"",'Phytopl Count'!N44*'Phytopl Count'!N$13/'Phytopl Count'!N$8) | ... AF44: =IF('Phytopl Count'!AF44=0,"",'Phytopl Count'!AF44*'Phytopl Count'!AF$13/'Phytopl Count'!AF$8)
C45: Order: | D45: Licmophorales | G45: =IF('Phytopl Count'!G45=0,"",'Phytopl Count'!G45*'Phytopl Count'!G$13/'Phytopl Count'!G$8) | H45: =IF('Phytopl Count'!H45=0,"",'Phytopl Count'!H45*'Phytopl Count'!H$13/'Phytopl Count'!H$8) | I45: =IF('Phytopl Count'!I45=0,"",'Phytopl Count'!I45*'Phytopl Count'!I$13/'Phytopl Count'!I$8) | J45: =IF('Phytopl Count'!J45=0,"",'Phytopl Count'!J45*'Phytopl Count'!J$13/'Phytopl Count'!J$8) | K45: =IF('Phytopl Count'!K45=0,"",'Phytopl Count'!K45*'Phytopl Count'!K$13/'Phytopl Count'!K$8) | L45: =IF('Phytopl Count'!L45=0,"",'Phytopl Count'!L45*'Phytopl Count'!L$13/'Phytopl Count'!L$8) | M45: =IF('Phytopl Count'!M45=0,"",'Phytopl Count'!M45*'Phytopl Count'!M$13/'Phytopl Count'!M$8) | N45: =IF('Phytopl Count'!N45=0,"",'Phytopl Count'!N45*'Phytopl Count'!N$13/'Phytopl Count'!N$8) | ... AF45: =IF('Phytopl Count'!AF45=0,"",'Phytopl Count'!AF45*'Phytopl Count'!AF$13/'Phytopl Count'!AF$8)
D46: Family: | E46: Licmophoraceae | G46: =IF('Phytopl Count'!G46=0,"",'Phytopl Count'!G46*'Phytopl Count'!G$13/'Phytopl Count'!G$8) | H46: =IF('Phytopl Count'!H46=0,"",'Phytopl Count'!H46*'Phytopl Count'!H$13/'Phytopl Count'!H$8) | I46: =IF('Phytopl Count'!I46=0,"",'Phytopl Count'!I46*'Phytopl Count'!I$13/'Phytopl Count'!I$8) | J46: =IF('Phytopl Count'!J46=0,"",'Phytopl Count'!J46*'Phytopl Count'!J$13/'Phytopl Count'!J$8) | K46: =IF('Phytopl Count'!K46=0,"",'Phytopl Count'!K46*'Phytopl Count'!K$13/'Phytopl Count'!K$8) | L46: =IF('Phytopl Count'!L46=0,"",'Phytopl Count'!L46*'Phytopl Count'!L$13/'Phytopl Count'!L$8) | M46: =IF('Phytopl Count'!M46=0,"",'Phytopl Count'!M46*'Phytopl Count'!M$13/'Phytopl Count'!M$8) | N46: =IF('Phytopl Count'!N46=0,"",'Phytopl Count'!N46*'Phytopl Count'!N$13/'Phytopl Count'!N$8) | ... AF46: =IF('Phytopl Count'!AF46=0,"",'Phytopl Count'!AF46*'Phytopl Count'!AF$13/'Phytopl Count'!AF$8)
E47: Genus: | F47: Licmophora | G47: =IF('Phytopl Count'!G47=0,"",'Phytopl Count'!G47*'Phytopl Count'!G$13/'Phytopl Count'!G$8) | H47: =IF('Phytopl Count'!H47=0,"",'Phytopl Count'!H47*'Phytopl Count'!H$13/'Phytopl Count'!H$8) | I47: =IF('Phytopl Count'!I47=0,"",'Phytopl Count'!I47*'Phytopl Count'!I$13/'Phytopl Count'!I$8) | J47: =IF('Phytopl Count'!J47=0,"",'Phytopl Count'!J47*'Phytopl Count'!J$13/'Phytopl Count'!J$8) -> 0.12011694 | K47: =IF('Phytopl Count'!K47=0,"",'Phytopl Count'!K47*'Phytopl Count'!K$13/'Phytopl Count'!K$8) | L47: =IF('Phytopl Count'!L47=0,"",'Phytopl Count'!L47*'Phytopl Count'!L$13/'Phytopl Count'!L$8) | M47: =IF('Phytopl Count'!M47=0,"",'Phytopl Count'!M47*'Phytopl Count'!M$13/'Phytopl Count'!M$8) | N47: =IF('Phytopl Count'!N47=0,"",'Phytopl Count'!N47*'Phytopl Count'!N$13/'Phytopl Count'!N$8) | ... AF47: =IF('Phytopl Count'!AF47=0,"",'Phytopl Count'!AF47*'Phytopl Count'!AF$13/'Phytopl Count'!AF$8)
...

Sheet Ln Data
A1: Log(n) of Phytoplankton data for Diversity calculations
F5: ='Phytopl Count'!F4 -> Sample Marking: | G5: ='Phytopl Count'!G4 -> S1 | H5: ='Phytopl Count'!H4 -> S2 | I5: ='Phytopl Count'!I4 -> S3 | J5: ='Phytopl Count'!J4 -> S4 | K5: ='Phytopl Count'!K4 -> S5 | L5: ='Phytopl Count'!L4 -> S6 | M5: ='Phytopl Count'!M4 -> S7 | ... AF5: ='Phytopl Count'!AF4 -> S26
F6: Date: | G6: 42337 | H6: 42337 | I6: 42337 | J6: 42337 | K6: 42337 | L6: 42337 | M6: 42337 | N6: 42337 | O6: 42337 | P6: 42337 | Q6: 42337 | R6: 42337 | S6: 42337 | T6: 42337 | U6: 42337 | V6: 42337 | W6: 42337 | X6: 42337 | Y6: 42337 | Z6: 42337 | AA6: 42337 | AB6: 42337 | AC6: 42337 | AD6: 42337 | AE6: 42337 | AF6: 42337
F7: Time: | G7: ='Phytopl Analysis'!#REF! -> #REF! | H7: ='Phytopl Analysis'!#REF! -> #REF! | I7: ='Phytopl Analysis'!#REF! -> #REF! | J7: ='Phytopl Analysis'!#REF! -> #REF! | K7: ='Phytopl Analysis'!#REF! -> #REF! | L7: ='Phytopl Analysis'!#REF! -> #REF! | M7: ='Phytopl Analysis'!#REF! -> #REF! | N7: ='Phytopl Analysis'!#REF! -> #REF! | ... AF7: ='Phytopl Analysis'!#REF! -> #REF!
A14: Phylum: | B14: Heterokontophyta | G14: =IF('Phytopl Count'!G14=0,"",('Phytopl Analysis'!G14*LN('Phytopl Analysis'!G14))) | H14: =IF('Phytopl Count'!H14=0,"",('Phytopl Analysis'!H14*LN('Phytopl Analysis'!H14))) | I14: =IF('Phytopl Count'!I14=0,"",('Phytopl Analysis'!I14*LN('Phytopl Analysis'!I14))) | J14: =IF('Phytopl Count'!J14=0,"",('Phytopl Analysis'!J14*LN('Phytopl Analysis'!J14))) | K14: =IF('Phytopl Count'!K14=0,"",('Phytopl Analysis'!K14*LN('Phytopl Analysis'!K14))) | L14: =IF('Phytopl Count'!L14=0,"",('Phytopl Analysis'!L14*LN('Phytopl Analysis'!L14))) | M14: =IF('Phytopl Count'!M14=0,"",('Phytopl Analysis'!M14*LN('Phytopl Analysis'!M14))) | N14: =IF('Phytopl Count'!N14=0,"",('Phytopl Analysis'!N14*LN('Phytopl Analysis'!N14))) | ... AF14: =IF('Phytopl Count'!AF14=0,"",('Phytopl Analysis'!AF14*LN('Phytopl Analysis'!AF14)))
B15: Class: | C15: Bacillariophyceae | G15: =IF('Phytopl Count'!G15=0,"",('Phytopl Analysis'!G15*LN('Phytopl Analysis'!G15))) | H15: =IF('Phytopl Count'!H15=0,"",('Phytopl Analysis'!H15*LN('Phytopl Analysis'!H15))) | I15: =IF('Phytopl Count'!I15=0,"",('Phytopl Analysis'!I15*LN('Phytopl Analysis'!I15))) | J15: =IF('Phytopl Count'!J15=0,"",('Phytopl Analysis'!J15*LN('Phytopl Analysis'!J15))) | K15: =IF('Phytopl Count'!K15=0,"",('Phytopl Analysis'!K15*LN('Phytopl Analysis'!K15))) | L15: =IF('Phytopl Count'!L15=0,"",('Phytopl Analysis'!L15*LN('Phytopl Analysis'!L15))) | M15: =IF('Phytopl Count'!M15=0,"",('Phytopl Analysis'!M15*LN('Phytopl Analysis'!M15))) | N15: =IF('Phytopl Count'!N15=0,"",('Phytopl Analysis'!N15*LN('Phytopl Analysis'!N15))) | ... AF15: =IF('Phytopl Count'!AF15=0,"",('Phytopl Analysis'!AF15*LN('Phytopl Analysis'!AF15)))
C16: Order: | D16: Bacillariales | G16: =IF('Phytopl Count'!G16=0,"",('Phytopl Analysis'!G16*LN('Phytopl Analysis'!G16))) | H16: =IF('Phytopl Count'!H16=0,"",('Phytopl Analysis'!H16*LN('Phytopl Analysis'!H16))) | I16: =IF('Phytopl Count'!I16=0,"",('Phytopl Analysis'!I16*LN('Phytopl Analysis'!I16))) | J16: =IF('Phytopl Count'!J16=0,"",('Phytopl Analysis'!J16*LN('Phytopl Analysis'!J16))) | K16: =IF('Phytopl Count'!K16=0,"",('Phytopl Analysis'!K16*LN('Phytopl Analysis'!K16))) | L16: =IF('Phytopl Count'!L16=0,"",('Phytopl Analysis'!L16*LN('Phytopl Analysis'!L16))) | M16: =IF('Phytopl Count'!M16=0,"",('Phytopl Analysis'!M16*LN('Phytopl Analysis'!M16))) | N16: =IF('Phytopl Count'!N16=0,"",('Phytopl Analysis'!N16*LN('Phytopl Analysis'!N16))) | ... AF16: =IF('Phytopl Count'!AF16=0,"",('Phytopl Analysis'!AF16*LN('Phytopl Analysis'!AF16)))
D17: Family: | E17: Bacillariaceae | G17: =IF('Phytopl Count'!G17=0,"",('Phytopl Analysis'!G17*LN('Phytopl Analysis'!G17))) | H17: =IF('Phytopl Count'!H17=0,"",('Phytopl Analysis'!H17*LN('Phytopl Analysis'!H17))) | I17: =IF('Phytopl Count'!I17=0,"",('Phytopl Analysis'!I17*LN('Phytopl Analysis'!I17))) | J17: =IF('Phytopl Count'!J17=0,"",('Phytopl Analysis'!J17*LN('Phytopl Analysis'!J17))) | K17: =IF('Phytopl Count'!K17=0,"",('Phytopl Analysis'!K17*LN('Phytopl Analysis'!K17))) | L17: =IF('Phytopl Count'!L17=0,"",('Phytopl Analysis'!L17*LN('Phytopl Analysis'!L17))) | M17: =IF('Phytopl Count'!M17=0,"",('Phytopl Analysis'!M17*LN('Phytopl Analysis'!M17))) | N17: =IF('Phytopl Count'!N17=0,"",('Phytopl Analysis'!N17*LN('Phytopl Analysis'!N17))) | ... AF17: =IF('Phytopl Count'!AF17=0,"",('Phytopl Analysis'!AF17*LN('Phytopl Analysis'!AF17)))
F18: Bacillaria | G18: =IF('Phytopl Count'!G18=0,"",('Phytopl Analysis'!G18*LN('Phytopl Analysis'!G18))) | H18: =IF('Phytopl Count'!H18=0,"",('Phytopl Analysis'!H18*LN('Phytopl Analysis'!H18))) | I18: =IF('Phytopl Count'!I18=0,"",('Phytopl Analysis'!I18*LN('Phytopl Analysis'!I18))) | J18: =IF('Phytopl Count'!J18=0,"",('Phytopl Analysis'!J18*LN('Phytopl Analysis'!J18))) | K18: =IF('Phytopl Count'!K18=0,"",('Phytopl Analysis'!K18*LN('Phytopl Analysis'!K18))) | L18: =IF('Phytopl Count'!L18=0,"",('Phytopl Analysis'!L18*LN('Phytopl Analysis'!L18))) | M18: =IF('Phytopl Count'!M18=0,"",('Phytopl Analysis'!M18*LN('Phytopl Analysis'!M18))) | N18: =IF('Phytopl Count'!N18=0,"",('Phytopl Analysis'!N18*LN('Phytopl Analysis'!N18))) | ... AF18: =IF('Phytopl Count'!AF18=0,"",('Phytopl Analysis'!AF18*LN('Phytopl Analysis'!AF18)))
E19: Genus: | F19: Cylindrotheca | G19: =IF('Phytopl Count'!G19=0,"",('Phytopl Analysis'!G19*LN('Phytopl Analysis'!G19))) | H19: =IF('Phytopl Count'!H19=0,"",('Phytopl Analysis'!H19*LN('Phytopl Analysis'!H19))) | I19: =IF('Phytopl Count'!I19=0,"",('Phytopl Analysis'!I19*LN('Phytopl Analysis'!I19))) | J19: =IF('Phytopl Count'!J19=0,"",('Phytopl Analysis'!J19*LN('Phytopl Analysis'!J19))) | K19: =IF('Phytopl Count'!K19=0,"",('Phytopl Analysis'!K19*LN('Phytopl Analysis'!K19))) | L19: =IF('Phytopl Count'!L19=0,"",('Phytopl Analysis'!L19*LN('Phytopl Analysis'!L19))) | M19: =IF('Phytopl Count'!M19=0,"",('Phytopl Analysis'!M19*LN('Phytopl Analysis'!M19))) | N19: =IF('Phytopl Count'!N19=0,"",('Phytopl Analysis'!N19*LN('Phytopl Analysis'!N19))) | ... AF19: =IF('Phytopl Count'!AF19=0,"",('Phytopl Analysis'!AF19*LN('Phytopl Analysis'!AF19)))
F20: Pseudo-nitzschia | G20: =IF('Phytopl Count'!G20=0,"",('Phytopl Analysis'!G20*LN('Phytopl Analysis'!G20))) | H20: =IF('Phytopl Count'!H20=0,"",('Phytopl Analysis'!H20*LN('Phytopl Analysis'!H20))) | I20: =IF('Phytopl Count'!I20=0,"",('Phytopl Analysis'!I20*LN('Phytopl Analysis'!I20))) | J20: =IF('Phytopl Count'!J20=0,"",('Phytopl Analysis'!J20*LN('Phytopl Analysis'!J20))) | K20: =IF('Phytopl Count'!K20=0,"",('Phytopl Analysis'!K20*LN('Phytopl Analysis'!K20))) | L20: =IF('Phytopl Count'!L20=0,"",('Phytopl Analysis'!L20*LN('Phytopl Analysis'!L20))) | M20: =IF('Phytopl Count'!M20=0,"",('Phytopl Analysis'!M20*LN('Phytopl Analysis'!M20))) | N20: =IF('Phytopl Count'!N20=0,"",('Phytopl Analysis'!N20*LN('Phytopl Analysis'!N20))) | ... AF20: =IF('Phytopl Count'!AF20=0,"",('Phytopl Analysis'!AF20*LN('Phytopl Analysis'!AF20)))
F21: Nitzschia | G21: =IF('Phytopl Count'!G21=0,"",('Phytopl Analysis'!G21*LN('Phytopl Analysis'!G21))) -> -0.29676304 | H21: =IF('Phytopl Count'!H21=0,"",('Phytopl Analysis'!H21*LN('Phytopl Analysis'!H21))) -> 1.9271464 | I21: =IF('Phytopl Count'!I21=0,"",('Phytopl Analysis'!I21*LN('Phytopl Analysis'!I21))) -> 0.12814377 | J21: =IF('Phytopl Count'!J21=0,"",('Phytopl Analysis'!J21*LN('Phytopl Analysis'!J21))) -> -0.33986615 | K21: =IF('Phytopl Count'!K21=0,"",('Phytopl Analysis'!K21*LN('Phytopl Analysis'!K21))) -> -0.24664217 | L21: =IF('Phytopl Count'!L21=0,"",('Phytopl Analysis'!L21*LN('Phytopl Analysis'!L21))) -> -0.20217432 | M21: =IF('Phytopl Count'!M21=0,"",('Phytopl Analysis'!M21*LN('Phytopl Analysis'!M21))) -> -0.2021772 | N21: =IF('Phytopl Count'!N21=0,"",('Phytopl Analysis'!N21*LN('Phytopl Analysis'!N21))) -> 0.66136293 | ... AF21: =IF('Phytopl Count'!AF21=0,"",('Phytopl Analysis'!AF21*LN('Phytopl Analysis'!AF21))) -> -0.26326443
C22: Order: | D22: Achnanthales | G22: =IF('Phytopl Count'!G22=0,"",('Phytopl Analysis'!G22*LN('Phytopl Analysis'!G22))) | H22: =IF('Phytopl Count'!H22=0,"",('Phytopl Analysis'!H22*LN('Phytopl Analysis'!H22))) | I22: =IF('Phytopl Count'!I22=0,"",('Phytopl Analysis'!I22*LN('Phytopl Analysis'!I22))) | J22: =IF('Phytopl Count'!J22=0,"",('Phytopl Analysis'!J22*LN('Phytopl Analysis'!J22))) | K22: =IF('Phytopl Count'!K22=0,"",('Phytopl Analysis'!K22*LN('Phytopl Analysis'!K22))) | L22: =IF('Phytopl Count'!L22=0,"",('Phytopl Analysis'!L22*LN('Phytopl Analysis'!L22))) | M22: =IF('Phytopl Count'!M22=0,"",('Phytopl Analysis'!M22*LN('Phytopl Analysis'!M22))) | N22: =IF('Phytopl Count'!N22=0,"",('Phytopl Analysis'!N22*LN('Phytopl Analysis'!N22))) | ... AF22: =IF('Phytopl Count'!AF22=0,"",('Phytopl Analysis'!AF22*LN('Phytopl Analysis'!AF22)))
D23: Family: | E23: Achnanthaceae | G23: =IF('Phytopl Count'!G23=0,"",('Phytopl Analysis'!G23*LN('Phytopl Analysis'!G23))) | H23: =IF('Phytopl Count'!H23=0,"",('Phytopl Analysis'!H23*LN('Phytopl Analysis'!H23))) | I23: =IF('Phytopl Count'!I23=0,"",('Phytopl Analysis'!I23*LN('Phytopl Analysis'!I23))) | J23: =IF('Phytopl Count'!J23=0,"",('Phytopl Analysis'!J23*LN('Phytopl Analysis'!J23))) | K23: =IF('Phytopl Count'!K23=0,"",('Phytopl Analysis'!K23*LN('Phytopl Analysis'!K23))) | L23: =IF('Phytopl Count'!L23=0,"",('Phytopl Analysis'!L23*LN('Phytopl Analysis'!L23))) | M23: =IF('Phytopl Count'!M23=0,"",('Phytopl Analysis'!M23*LN('Phytopl Analysis'!M23))) | N23: =IF('Phytopl Count'!N23=0,"",('Phytopl Analysis'!N23*LN('Phytopl Analysis'!N23))) | ... AF23: =IF('Phytopl Count'!AF23=0,"",('Phytopl Analysis'!AF23*LN('Phytopl Analysis'!AF23)))
E24: Genus: | F24: Achnanthes | G24: =IF('Phytopl Count'!G24=0,"",('Phytopl Analysis'!G24*LN('Phytopl Analysis'!G24))) | H24: =IF('Phytopl Count'!H24=0,"",('Phytopl Analysis'!H24*LN('Phytopl Analysis'!H24))) | I24: =IF('Phytopl Count'!I24=0,"",('Phytopl Analysis'!I24*LN('Phytopl Analysis'!I24))) | J24: =IF('Phytopl Count'!J24=0,"",('Phytopl Analysis'!J24*LN('Phytopl Analysis'!J24))) | K24: =IF('Phytopl Count'!K24=0,"",('Phytopl Analysis'!K24*LN('Phytopl Analysis'!K24))) | L24: =IF('Phytopl Count'!L24=0,"",('Phytopl Analysis'!L24*LN('Phytopl Analysis'!L24))) | M24: =IF('Phytopl Count'!M24=0,"",('Phytopl Analysis'!M24*LN('Phytopl Analysis'!M24))) | N24: =IF('Phytopl Count'!N24=0,"",('Phytopl Analysis'!N24*LN('Phytopl Analysis'!N24))) | ... AF24: =IF('Phytopl Count'!AF24=0,"",('Phytopl Analysis'!AF24*LN('Phytopl Analysis'!AF24)))
D25: Family: | E25: Cocconeidaceae | G25: =IF('Phytopl Count'!G25=0,"",('Phytopl Analysis'!G25*LN('Phytopl Analysis'!G25))) | H25: =IF('Phytopl Count'!H25=0,"",('Phytopl Analysis'!H25*LN('Phytopl Analysis'!H25))) | I25: =IF('Phytopl Count'!I25=0,"",('Phytopl Analysis'!I25*LN('Phytopl Analysis'!I25))) | J25: =IF('Phytopl Count'!J25=0,"",('Phytopl Analysis'!J25*LN('Phytopl Analysis'!J25))) | K25: =IF('Phytopl Count'!K25=0,"",('Phytopl Analysis'!K25*LN('Phytopl Analysis'!K25))) | L25: =IF('Phytopl Count'!L25=0,"",('Phytopl Analysis'!L25*LN('Phytopl Analysis'!L25))) | M25: =IF('Phytopl Count'!M25=0,"",('Phytopl Analysis'!M25*LN('Phytopl Analysis'!M25))) | N25: =IF('Phytopl Count'!N25=0,"",('Phytopl Analysis'!N25*LN('Phytopl Analysis'!N25))) | ... AF25: =IF('Phytopl Count'!AF25=0,"",('Phytopl Analysis'!AF25*LN('Phytopl Analysis'!AF25)))
E26: Genus: | F26: Cocconeis | G26: =IF('Phytopl Count'!G26=0,"",('Phytopl Analysis'!G26*LN('Phytopl Analysis'!G26))) | H26: =IF('Phytopl Count'!H26=0,"",('Phytopl Analysis'!H26*LN('Phytopl Analysis'!H26))) | I26: =IF('Phytopl Count'!I26=0,"",('Phytopl Analysis'!I26*LN('Phytopl Analysis'!I26))) | J26: =IF('Phytopl Count'!J26=0,"",('Phytopl Analysis'!J26*LN('Phytopl Analysis'!J26))) | K26: =IF('Phytopl Count'!K26=0,"",('Phytopl Analysis'!K26*LN('Phytopl Analysis'!K26))) | L26: =IF('Phytopl Count'!L26=0,"",('Phytopl Analysis'!L26*LN('Phytopl Analysis'!L26))) | M26: =IF('Phytopl Count'!M26=0,"",('Phytopl Analysis'!M26*LN('Phytopl Analysis'!M26))) | N26: =IF('Phytopl Count'!N26=0,"",('Phytopl Analysis'!N26*LN('Phytopl Analysis'!N26))) | ... AF26: =IF('Phytopl Count'!AF26=0,"",('Phytopl Analysis'!AF26*LN('Phytopl Analysis'!AF26)))
C27: Order: | D27: Fragilariales | G27: =IF('Phytopl Count'!G27=0,"",('Phytopl Analysis'!G27*LN('Phytopl Analysis'!G27))) | H27: =IF('Phytopl Count'!H27=0,"",('Phytopl Analysis'!H27*LN('Phytopl Analysis'!H27))) | I27: =IF('Phytopl Count'!I27=0,"",('Phytopl Analysis'!I27*LN('Phytopl Analysis'!I27))) | J27: =IF('Phytopl Count'!J27=0,"",('Phytopl Analysis'!J27*LN('Phytopl Analysis'!J27))) | K27: =IF('Phytopl Count'!K27=0,"",('Phytopl Analysis'!K27*LN('Phytopl Analysis'!K27))) | L27: =IF('Phytopl Count'!L27=0,"",('Phytopl Analysis'!L27*LN('Phytopl Analysis'!L27))) | M27: =IF('Phytopl Count'!M27=0,"",('Phytopl Analysis'!M27*LN('Phytopl Analysis'!M27))) | N27: =IF('Phytopl Count'!N27=0,"",('Phytopl Analysis'!N27*LN('Phytopl Analysis'!N27))) | ... AF27: =IF('Phytopl Count'!AF27=0,"",('Phytopl Analysis'!AF27*LN('Phytopl Analysis'!AF27)))
D28: Family: | E28: Fragilariaceae | G28: =IF('Phytopl Count'!G28=0,"",('Phytopl Analysis'!G28*LN('Phytopl Analysis'!G28))) | H28: =IF('Phytopl Count'!H28=0,"",('Phytopl Analysis'!H28*LN('Phytopl Analysis'!H28))) | I28: =IF('Phytopl Count'!I28=0,"",('Phytopl Analysis'!I28*LN('Phytopl Analysis'!I28))) | J28: =IF('Phytopl Count'!J28=0,"",('Phytopl Analysis'!J28*LN('Phytopl Analysis'!J28))) | K28: =IF('Phytopl Count'!K28=0,"",('Phytopl Analysis'!K28*LN('Phytopl Analysis'!K28))) | L28: =IF('Phytopl Count'!L28=0,"",('Phytopl Analysis'!L28*LN('Phytopl Analysis'!L28))) | M28: =IF('Phytopl Count'!M28=0,"",('Phytopl Analysis'!M28*LN('Phytopl Analysis'!M28))) | N28: =IF('Phytopl Count'!N28=0,"",('Phytopl Analysis'!N28*LN('Phytopl Analysis'!N28))) | ... AF28: =IF('Phytopl Count'!AF28=0,"",('Phytopl Analysis'!AF28*LN('Phytopl Analysis'!AF28)))
E29: Genus: | F29: Fragilaria | G29: =IF('Phytopl Count'!G29=0,"",('Phytopl Analysis'!G29*LN('Phytopl Analysis'!G29))) | H29: =IF('Phytopl Count'!H29=0,"",('Phytopl Analysis'!H29*LN('Phytopl Analysis'!H29))) | I29: =IF('Phytopl Count'!I29=0,"",('Phytopl Analysis'!I29*LN('Phytopl Analysis'!I29))) | J29: =IF('Phytopl Count'!J29=0,"",('Phytopl Analysis'!J29*LN('Phytopl Analysis'!J29))) | K29: =IF('Phytopl Count'!K29=0,"",('Phytopl Analysis'!K29*LN('Phytopl Analysis'!K29))) | L29: =IF('Phytopl Count'!L29=0,"",('Phytopl Analysis'!L29*LN('Phytopl Analysis'!L29))) | M29: =IF('Phytopl Count'!M29=0,"",('Phytopl Analysis'!M29*LN('Phytopl Analysis'!M29))) | N29: =IF('Phytopl Count'!N29=0,"",('Phytopl Analysis'!N29*LN('Phytopl Analysis'!N29))) | ... AF29: =IF('Phytopl Count'!AF29=0,"",('Phytopl Analysis'!AF29*LN('Phytopl Analysis'!AF29)))
D30: Family: | E30: Staurosiraceae | G30: =IF('Phytopl Count'!G30=0,"",('Phytopl Analysis'!G30*LN('Phytopl Analysis'!G30))) | H30: =IF('Phytopl Count'!H30=0,"",('Phytopl Analysis'!H30*LN('Phytopl Analysis'!H30))) | I30: =IF('Phytopl Count'!I30=0,"",('Phytopl Analysis'!I30*LN('Phytopl Analysis'!I30))) | J30: =IF('Phytopl Count'!J30=0,"",('Phytopl Analysis'!J30*LN('Phytopl Analysis'!J30))) | K30: =IF('Phytopl Count'!K30=0,"",('Phytopl Analysis'!K30*LN('Phytopl Analysis'!K30))) | L30: =IF('Phytopl Count'!L30=0,"",('Phytopl Analysis'!L30*LN('Phytopl Analysis'!L30))) | M30: =IF('Phytopl Count'!M30=0,"",('Phytopl Analysis'!M30*LN('Phytopl Analysis'!M30))) | N30: =IF('Phytopl Count'!N30=0,"",('Phytopl Analysis'!N30*LN('Phytopl Analysis'!N30))) | ... AF30: =IF('Phytopl Count'!AF30=0,"",('Phytopl Analysis'!AF30*LN('Phytopl Analysis'!AF30)))
E31: Genus: | F31: Staurosira | G31: =IF('Phytopl Count'!G31=0,"",('Phytopl Analysis'!G31*LN('Phytopl Analysis'!G31))) | H31: =IF('Phytopl Count'!H31=0,"",('Phytopl Analysis'!H31*LN('Phytopl Analysis'!H31))) | I31: =IF('Phytopl Count'!I31=0,"",('Phytopl Analysis'!I31*LN('Phytopl Analysis'!I31))) | J31: =IF('Phytopl Count'!J31=0,"",('Phytopl Analysis'!J31*LN('Phytopl Analysis'!J31))) | K31: =IF('Phytopl Count'!K31=0,"",('Phytopl Analysis'!K31*LN('Phytopl Analysis'!K31))) | L31: =IF('Phytopl Count'!L31=0,"",('Phytopl Analysis'!L31*LN('Phytopl Analysis'!L31))) | M31: =IF('Phytopl Count'!M31=0,"",('Phytopl Analysis'!M31*LN('Phytopl Analysis'!M31))) | N31: =IF('Phytopl Count'!N31=0,"",('Phytopl Analysis'!N31*LN('Phytopl Analysis'!N31))) | ... AF31: =IF('Phytopl Count'!AF31=0,"",('Phytopl Analysis'!AF31*LN('Phytopl Analysis'!AF31)))
C32: Order: | D32: Surirellales | G32: =IF('Phytopl Count'!G32=0,"",('Phytopl Analysis'!G32*LN('Phytopl Analysis'!G32))) | H32: =IF('Phytopl Count'!H32=0,"",('Phytopl Analysis'!H32*LN('Phytopl Analysis'!H32))) | I32: =IF('Phytopl Count'!I32=0,"",('Phytopl Analysis'!I32*LN('Phytopl Analysis'!I32))) | J32: =IF('Phytopl Count'!J32=0,"",('Phytopl Analysis'!J32*LN('Phytopl Analysis'!J32))) | K32: =IF('Phytopl Count'!K32=0,"",('Phytopl Analysis'!K32*LN('Phytopl Analysis'!K32))) | L32: =IF('Phytopl Count'!L32=0,"",('Phytopl Analysis'!L32*LN('Phytopl Analysis'!L32))) | M32: =IF('Phytopl Count'!M32=0,"",('Phytopl Analysis'!M32*LN('Phytopl Analysis'!M32))) | N32: =IF('Phytopl Count'!N32=0,"",('Phytopl Analysis'!N32*LN('Phytopl Analysis'!N32))) | ... AF32: =IF('Phytopl Count'!AF32=0,"",('Phytopl Analysis'!AF32*LN('Phytopl Analysis'!AF32)))
D33: Family: | E33: Entomoneidaceae | G33: =IF('Phytopl Count'!G33=0,"",('Phytopl Analysis'!G33*LN('Phytopl Analysis'!G33))) | H33: =IF('Phytopl Count'!H33=0,"",('Phytopl Analysis'!H33*LN('Phytopl Analysis'!H33))) | I33: =IF('Phytopl Count'!I33=0,"",('Phytopl Analysis'!I33*LN('Phytopl Analysis'!I33))) | J33: =IF('Phytopl Count'!J33=0,"",('Phytopl Analysis'!J33*LN('Phytopl Analysis'!J33))) | K33: =IF('Phytopl Count'!K33=0,"",('Phytopl Analysis'!K33*LN('Phytopl Analysis'!K33))) | L33: =IF('Phytopl Count'!L33=0,"",('Phytopl Analysis'!L33*LN('Phytopl Analysis'!L33))) | M33: =IF('Phytopl Count'!M33=0,"",('Phytopl Analysis'!M33*LN('Phytopl Analysis'!M33))) | N33: =IF('Phytopl Count'!N33=0,"",('Phytopl Analysis'!N33*LN('Phytopl Analysis'!N33))) | ... AF33: =IF('Phytopl Count'!AF33=0,"",('Phytopl Analysis'!AF33*LN('Phytopl Analysis'!AF33)))
E34: Genus: | F34: Entomoneis | G34: =IF('Phytopl Count'!G34=0,"",('Phytopl Analysis'!G34*LN('Phytopl Analysis'!G34))) | H34: =IF('Phytopl Count'!H34=0,"",('Phytopl Analysis'!H34*LN('Phytopl Analysis'!H34))) | I34: =IF('Phytopl Count'!I34=0,"",('Phytopl Analysis'!I34*LN('Phytopl Analysis'!I34))) | J34: =IF('Phytopl Count'!J34=0,"",('Phytopl Analysis'!J34*LN('Phytopl Analysis'!J34))) | K34: =IF('Phytopl Count'!K34=0,"",('Phytopl Analysis'!K34*LN('Phytopl Analysis'!K34))) | L34: =IF('Phytopl Count'!L34=0,"",('Phytopl Analysis'!L34*LN('Phytopl Analysis'!L34))) | M34: =IF('Phytopl Count'!M34=0,"",('Phytopl Analysis'!M34*LN('Phytopl Analysis'!M34))) | N34: =IF('Phytopl Count'!N34=0,"",('Phytopl Analysis'!N34*LN('Phytopl Analysis'!N34))) | ... AF34: =IF('Phytopl Count'!AF34=0,"",('Phytopl Analysis'!AF34*LN('Phytopl Analysis'!AF34)))
D35: Family: | E35: Surirellaceae | G35: =IF('Phytopl Count'!G35=0,"",('Phytopl Analysis'!G35*LN('Phytopl Analysis'!G35))) | H35: =IF('Phytopl Count'!H35=0,"",('Phytopl Analysis'!H35*LN('Phytopl Analysis'!H35))) | I35: =IF('Phytopl Count'!I35=0,"",('Phytopl Analysis'!I35*LN('Phytopl Analysis'!I35))) | J35: =IF('Phytopl Count'!J35=0,"",('Phytopl Analysis'!J35*LN('Phytopl Analysis'!J35))) | K35: =IF('Phytopl Count'!K35=0,"",('Phytopl Analysis'!K35*LN('Phytopl Analysis'!K35))) | L35: =IF('Phytopl Count'!L35=0,"",('Phytopl Analysis'!L35*LN('Phytopl Analysis'!L35))) | M35: =IF('Phytopl Count'!M35=0,"",('Phytopl Analysis'!M35*LN('Phytopl Analysis'!M35))) | N35: =IF('Phytopl Count'!N35=0,"",('Phytopl Analysis'!N35*LN('Phytopl Analysis'!N35))) | ... AF35: =IF('Phytopl Count'!AF35=0,"",('Phytopl Analysis'!AF35*LN('Phytopl Analysis'!AF35)))
