Workbook

Sheet Sample Info
C3: ALCHEMY Laboratory & Services Sdn. Bhd. (Company No: 903112 K) | F3: SAMM NO. 554
C4: 326B, 1st Floor, Lot 2520, Jalan Hiliran, Mukim Losong,
C5: 20300, Kuala Terengganu, Terengganu, Malaysia.
C6: Tel: +609- 622 4166, Fax: +609- 622 4177
E8: Report no: | F8: TR/BZ/14748/25 - TR/BZ/14757/25
E10: Date:
E11: Pages:
C13: CERTIFICATE OF ANALYSIS
B14: Zooplankton: Sample Information
B16: Client Name: | C16: Permulab Sdn. Bhd.
B17: Client Address: | C17: A-G-16, Merchant Square@Tropicana,
C18: Jalan Tropicana Selatan 1, PJU 3,
C19: 47410 Petaling Jaya,
C20: Selangor
B22: Type of Sample: | C22: Marine Water
B23: Sample Marking: | C23: PLW-25-274014-1 - PLW-25-274014-5, PLW-25-274016-1 - PLW-25-274016-5
B24: Number of samples: | C24: 10
B25: Date Received: | C25: 45948
B26: Gear used: | C26: Plankton net | G26: Mouth surface area:
B27: Net diameter: | C27: 25 | D27: cm | G27: =PI()*(C27/200)^2 -> 0.049087385 | H27: m2
B28: Net mesh: | C28: 150 | D28: mm
B29: Tow type: | C29: Vertical
B30: Filtered volume: | C30: (see results table)
B31: Method of Analysis: | C31: SOP No.: ALC_B_002
B32: Comments: | C32: based on APHA 10200 G
B35: The details above are provided by the client. The reported results refer to sample(s) submitted by client only.
B37: Authorized by:
B41: …………………………………………..
B42: Muhammad Firdaus bin Daud
B43: Marine Biologist
B44: BSc. (Marine Science)

Sheet Sample List
A1: ALCHEMY Laboratory & Services Sdn Bhd
B3: Client: | C3: Permulab Sdn. Bhd.
B4: Institution: | C4: Permulab Sdn. Bhd.
B5: Description: | C5: Marine Water
B7: Date Received | C7: Sample Marking | D7: Date of Analysis | E7: Reference ID | F7: Report No.
A8: 1 | B8: 45918 | C8: PLW-25-274014-1 | D8: 45953 | E8: BZ14748 | F8: TR/BZ/14748/25
A9: 2 | B9: 45918 | C9: PLW-25-274014-2 | D9: 45953 | E9: BZ14749 | F9: TR/BZ/14749/25
A10: 3 | B10: 45918 | C10: PLW-25-274014-3 | D10: 45953 | E10: BZ14750 | F10: TR/BZ/14750/25
A11: 4 | B11: 45918 | C11: PLW-25-274014-4 | D11: 45953 | E11: BZ14751 | F11: TR/BZ/14751/25
A12: 5 | B12: 45918 | C12: PLW-25-274014-5 | D12: 45953 | E12: BZ14752 | F12: TR/BZ/14752/25
A13: 6 | B13: 45918 | C13: PLW-25-274016-1 | D13: 45953 | E13: BZ14753 | F13: TR/BZ/14753/25
A14: 7 | B14: 45918 | C14: PLW-25-274016-2 | D14: 45953 | E14: BZ14754 | F14: TR/BZ/14754/25
A15: 8 | B15: 45918 | C15: PLW-25-274016-3 | D15: 45953 | E15: BZ14755 | F15: TR/BZ/14755/25
A16: 9 | B16: 45918 | C16: PLW-25-274016-4 | D16: 45953 | E16: BZ14756 | F16: TR/BZ/14756/25
A17: 10 | B17: 45918 | C17: PLW-25-274016-5 | D17: 45953 | E17: BZ14757 | F17: TR/BZ/14757/25

Sheet Zoopl Count
A1: ALCHEMY Laboratory & Services Sdn Bhd
A2: Zooplankton Data Sheet : Raw Count Data
A3: ` | F3: Reference ID: | G3: BZ14748 | H3: BZ14749 | I3: BZ14750 | J3: BZ14751 | K3: BZ14752 | L3: BZ14753 | M3: BZ14754 | N3: BZ14755 | O3: BZ14756 | P3: BZ14757
F4: Sample Marking: | G4: PLW-25-274014-1 | H4: PLW-25-274014-2 | I4: PLW-25-274014-3 | J4: PLW-25-274014-4 | K4: PLW-25-274014-5 | L4: PLW-25-274016-1 | M4: PLW-25-274016-2 | N4: PLW-25-274016-3 | O4: PLW-25-274016-4 | P4: PLW-25-274016-5
F5: Date:
F6: Time:
F7: Tow distance(m): | G7: 5 | H7: 5 | I7: 5 | J7: 5 | K7: 5 | L7: 5 | M7: 5 | N7: 5 | O7: 5 | P7: 5
F8: Volume filtered (l): | G8: ='Sample Info'!$G$27*'Zoopl Count'!G7*1000 -> 245.43693 | H8: ='Sample Info'!$G$27*'Zoopl Count'!H7*1000 -> 245.43693 | I8: ='Sample Info'!$G$27*'Zoopl Count'!I7*1000 -> 245.43693 | J8: ='Sample Info'!$G$27*'Zoopl Count'!J7*1000 -> 245.43693 | K8: ='Sample Info'!$G$27*'Zoopl Count'!K7*1000 -> 245.43693 | L8: ='Sample Info'!$G$27*'Zoopl Count'!L7*1000 -> 245.43693 | M8: ='Sample Info'!$G$27*'Zoopl Count'!M7*1000 -> 245.43693 | N8: ='Sample Info'!$G$27*'Zoopl Count'!N7*1000 -> 245.43693 | ... P8: ='Sample Info'!$G$27*'Zoopl Count'!P7*1000 -> 245.43693
F9: Split factor: | G9: 5 | H9: 4 | I9: 3 | J9: 5 | K9: 5 | L9: 7 | M9: 5 | N9: 3 | O9: 8 | P9: 5
A10: Phylum: | B10: Foraminifera
B11: Class: | C11: Globothalamea
C12: Order: | D12: Rotaliida
D13: Family: | E13: Bolivinitinae
E14: Genus: | F14: Bolivina
D15: Family: | E15: Globigerinidae
E16: Genus: | F16: Globigerina
D17: Family: | E17: Globorotaliidae
E18: Genus: | F18: Globorotalia
D19: Family: | E19: Orbulininae
E20: Genus: | F20: Orbulina
D21: Family: | E21: Calcarinidae
E22: Genus: | F22: Baculogypsina
B24: Class: | C24: Tubothalamea
C25: Order: | D25: Miliolida
D26: Family: | E26: Spiroloculinidae
E27: Genus: | F27: Spiroloculina
B29: Class: | C29: Nodosariata
C30: Order: | D30: Vaginulinida
D31: Family: | E31: Vaginulinidae
E32: Genus: | F32: Planularia
F33: Lenticulina
F34: Vaginulina
A36: Phylum: | B36: Radiozoa
B37: Class: | C37: Acantharia
C38: Order: | D38: Arthracanthida
D39: Family: | E39: Acanthometridae
E40: Genus: | F40: Acanthometron
A43: Phylum: | B43: Ciliophora
B44: Class: | C44: Oligotrichea
C45: Order: | D45: Choreotrichida
...

Sheet Zoopl Analysis
A1: ALCHEMY Laboratory & Services Sdn Bhd
A2: Zooplankton Data Sheet : Analysed Zooplankton samples
F5: Density in units per litre
F6: ='Zoopl Count'!F3 -> Reference ID: | G6: ='Zoopl Count'!G3 -> BZ14748 | H6: ='Zoopl Count'!H3 -> BZ14749 | I6: ='Zoopl Count'!I3 -> BZ14750 | J6: ='Zoopl Count'!J3 -> BZ14751 | K6: ='Zoopl Count'!K3 -> BZ14752 | L6: ='Zoopl Count'!L3 -> BZ14753 | M6: ='Zoopl Count'!M3 -> BZ14754 | ... P6: ='Zoopl Count'!P3 -> BZ14757
F7: ='Zoopl Count'!F4 -> Sample Marking: | G7: ='Zoopl Count'!G4 -> PLW-25-274014-1 | H7: ='Zoopl Count'!H4 -> PLW-25-274014-2 | I7: ='Zoopl Count'!I4 -> PLW-25-274014-3 | J7: ='Zoopl Count'!J4 -> PLW-25-274014-4 | K7: ='Zoopl Count'!K4 -> PLW-25-274014-5 | L7: ='Zoopl Count'!L4 -> PLW-25-274016-1 | M7: ='Zoopl Count'!M4 -> PLW-25-274016-2 | ... P7: ='Zoopl Count'!P4 -> PLW-25-274016-5
F8: Volume filtered (l): | G8: ='Zoopl Count'!G8 -> 245.43693 | H8: ='Zoopl Count'!H8 -> 245.43693 | I8: ='Zoopl Count'!I8 -> 245.43693 | J8: ='Zoopl Count'!J8 -> 245.43693 | K8: ='Zoopl Count'!K8 -> 245.43693 | L8: ='Zoopl Count'!L8 -> 245.43693 | M8: ='Zoopl Count'!M8 -> 245.43693 | N8: ='Zoopl Count'!N8 -> 245.43693 | ... P8: ='Zoopl Count'!P8 -> 245.43693
F9: Split factor: | G9: ='Zoopl Count'!G9 -> 5 | H9: ='Zoopl Count'!H9 -> 4 | I9: ='Zoopl Count'!I9 -> 3 | J9: ='Zoopl Count'!J9 -> 5 | K9: ='Zoopl Count'!K9 -> 5 | L9: ='Zoopl Count'!L9 -> 7 | M9: ='Zoopl Count'!M9 -> 5 | N9: ='Zoopl Count'!N9 -> 3 | ... P9: ='Zoopl Count'!P9 -> 5
A10: Phylum: | B10: Foraminifera | G10: =IF('Zoopl Count'!G10="","",'Zoopl Count'!G10*(2^G$9)/G$8) | H10: =IF('Zoopl Count'!H10="","",'Zoopl Count'!H10*(2^H$9)/H$8) | I10: =IF('Zoopl Count'!I10="","",'Zoopl Count'!I10*(2^I$9)/I$8) | J10: =IF('Zoopl Count'!J10="","",'Zoopl Count'!J10*(2^J$9)/J$8) | K10: =IF('Zoopl Count'!K10="","",'Zoopl Count'!K10*(2^K$9)/K$8) | L10: =IF('Zoopl Count'!L10="","",'Zoopl Count'!L10*(2^L$9)/L$8) | M10: =IF('Zoopl Count'!M10="","",'Zoopl Count'!M10*(2^M$9)/M$8) | N10: =IF('Zoopl Count'!N10="","",'Zoopl Count'!N10*(2^N$9)/N$8) | ... P10: =IF('Zoopl Count'!P10="","",'Zoopl Count'!P10*(2^P$9)/P$8)
B11: Class: | C11: Globothalamea | G11: =IF('Zoopl Count'!G11="","",'Zoopl Count'!G11*(2^G$9)/G$8) | H11: =IF('Zoopl Count'!H11="","",'Zoopl Count'!H11*(2^H$9)/H$8) | I11: =IF('Zoopl Count'!I11="","",'Zoopl Count'!I11*(2^I$9)/I$8) | J11: =IF('Zoopl Count'!J11="","",'Zoopl Count'!J11*(2^J$9)/J$8) | K11: =IF('Zoopl Count'!K11="","",'Zoopl Count'!K11*(2^K$9)/K$8) | L11: =IF('Zoopl Count'!L11="","",'Zoopl Count'!L11*(2^L$9)/L$8) | M11: =IF('Zoopl Count'!M11="","",'Zoopl Count'!M11*(2^M$9)/M$8) | N11: =IF('Zoopl Count'!N11="","",'Zoopl Count'!N11*(2^N$9)/N$8) | ... P11: =IF('Zoopl Count'!P11="","",'Zoopl Count'!P11*(2^P$9)/P$8)
C12: Order: | D12: Rotaliida | G12: =IF('Zoopl Count'!G12="","",'Zoopl Count'!G12*(2^G$9)/G$8) | H12: =IF('Zoopl Count'!H12="","",'Zoopl Count'!H12*(2^H$9)/H$8) | I12: =IF('Zoopl Count'!I12="","",'Zoopl Count'!I12*(2^I$9)/I$8) | J12: =IF('Zoopl Count'!J12="","",'Zoopl Count'!J12*(2^J$9)/J$8) | K12: =IF('Zoopl Count'!K12="","",'Zoopl Count'!K12*(2^K$9)/K$8) | L12: =IF('Zoopl Count'!L12="","",'Zoopl Count'!L12*(2^L$9)/L$8) | M12: =IF('Zoopl Count'!M12="","",'Zoopl Count'!M12*(2^M$9)/M$8) | N12: =IF('Zoopl Count'!N12="","",'Zoopl Count'!N12*(2^N$9)/N$8) | ... P12: =IF('Zoopl Count'!P12="","",'Zoopl Count'!P12*(2^P$9)/P$8)
D13: Family: | E13: Bolivinitinae | G13: =IF('Zoopl Count'!G13="","",'Zoopl Count'!G13*(2^G$9)/G$8) | H13: =IF('Zoopl Count'!H13="","",'Zoopl Count'!H13*(2^H$9)/H$8) | I13: =IF('Zoopl Count'!I13="","",'Zoopl Count'!I13*(2^I$9)/I$8) | J13: =IF('Zoopl Count'!J13="","",'Zoopl Count'!J13*(2^J$9)/J$8) | K13: =IF('Zoopl Count'!K13="","",'Zoopl Count'!K13*(2^K$9)/K$8) | L13: =IF('Zoopl Count'!L13="","",'Zoopl Count'!L13*(2^L$9)/L$8) | M13: =IF('Zoopl Count'!M13="","",'Zoopl Count'!M13*(2^M$9)/M$8) | N13: =IF('Zoopl Count'!N13="","",'Zoopl Count'!N13*(2^N$9)/N$8) | ... P13: =IF('Zoopl Count'!P13="","",'Zoopl Count'!P13*(2^P$9)/P$8)
E14: Genus: | F14: Bolivina | G14: =IF('Zoopl Count'!G14="","",'Zoopl Count'!G14*(2^G$9)/G$8) | H14: =IF('Zoopl Count'!H14="","",'Zoopl Count'!H14*(2^H$9)/H$8) | I14: =IF('Zoopl Count'!I14="","",'Zoopl Count'!I14*(2^I$9)/I$8) | J14: =IF('Zoopl Count'!J14="","",'Zoopl Count'!J14*(2^J$9)/J$8) | K14: =IF('Zoopl Count'!K14="","",'Zoopl Count'!K14*(2^K$9)/K$8) | L14: =IF('Zoopl Count'!L14="","",'Zoopl Count'!L14*(2^L$9)/L$8) | M14: =IF('Zoopl Count'!M14="","",'Zoopl Count'!M14*(2^M$9)/M$8) | N14: =IF('Zoopl Count'!N14="","",'Zoopl Count'!N14*(2^N$9)/N$8) | ... P14: =IF('Zoopl Count'!P14="","",'Zoopl Count'!P14*(2^P$9)/P$8)
D15: Family: | E15: Globigerinidae | G15: =IF('Zoopl Count'!G15="","",'Zoopl Count'!G15*(2^G$9)/G$8) | H15: =IF('Zoopl Count'!H15="","",'Zoopl Count'!H15*(2^H$9)/H$8) | I15: =IF('Zoopl Count'!I15="","",'Zoopl Count'!I15*(2^I$9)/I$8) | J15: =IF('Zoopl Count'!J15="","",'Zoopl Count'!J15*(2^J$9)/J$8) | K15: =IF('Zoopl Count'!K15="","",'Zoopl Count'!K15*(2^K$9)/K$8) | L15: =IF('Zoopl Count'!L15="","",'Zoopl Count'!L15*(2^L$9)/L$8) | M15: =IF('Zoopl Count'!M15="","",'Zoopl Count'!M15*(2^M$9)/M$8) | N15: =IF('Zoopl Count'!N15="","",'Zoopl Count'!N15*(2^N$9)/N$8) | ... P15: =IF('Zoopl Count'!P15="","",'Zoopl Count'!P15*(2^P$9)/P$8)
E16: Genus: | F16: Globigerina | G16: =IF('Zoopl Count'!G16="","",'Zoopl Count'!G16*(2^G$9)/G$8) | H16: =IF('Zoopl Count'!H16="","",'Zoopl Count'!H16*(2^H$9)/H$8) | I16: =IF('Zoopl Count'!I16="","",'Zoopl Count'!I16*(2^I$9)/I$8) | J16: =IF('Zoopl Count'!J16="","",'Zoopl Count'!J16*(2^J$9)/J$8) | K16: =IF('Zoopl Count'!K16="","",'Zoopl Count'!K16*(2^K$9)/K$8) | L16: =IF('Zoopl Count'!L16="","",'Zoopl Count'!L16*(2^L$9)/L$8) | M16: =IF('Zoopl Count'!M16="","",'Zoopl Count'!M16*(2^M$9)/M$8) | N16: =IF('Zoopl Count'!N16="","",'Zoopl Count'!N16*(2^N$9)/N$8) | ... P16: =IF('Zoopl Count'!P16="","",'Zoopl Count'!P16*(2^P$9)/P$8)
D17: Family: | E17: Globorotaliidae | G17: =IF('Zoopl Count'!G17="","",'Zoopl Count'!G17*(2^G$9)/G$8) | H17: =IF('Zoopl Count'!H17="","",'Zoopl Count'!H17*(2^H$9)/H$8) | I17: =IF('Zoopl Count'!I17="","",'Zoopl Count'!I17*(2^I$9)/I$8) | J17: =IF('Zoopl Count'!J17="","",'Zoopl Count'!J17*(2^J$9)/J$8) | K17: =IF('Zoopl Count'!K17="","",'Zoopl Count'!K17*(2^K$9)/K$8) | L17: =IF('Zoopl Count'!L17="","",'Zoopl Count'!L17*(2^L$9)/L$8) | M17: =IF('Zoopl Count'!M17="","",'Zoopl Count'!M17*(2^M$9)/M$8) | N17: =IF('Zoopl Count'!N17="","",'Zoopl Count'!N17*(2^N$9)/N$8) | ... P17: =IF('Zoopl Count'!P17="","",'Zoopl Count'!P17*(2^P$9)/P$8)
E18: Genus: | F18: Globorotalia | G18: =IF('Zoopl Count'!G18="","",'Zoopl Count'!G18*(2^G$9)/G$8) | H18: =IF('Zoopl Count'!H18="","",'Zoopl Count'!H18*(2^H$9)/H$8) | I18: =IF('Zoopl Count'!I18="","",'Zoopl Count'!I18*(2^I$9)/I$8) | J18: =IF('Zoopl Count'!J18="","",'Zoopl Count'!J18*(2^J$9)/J$8) | K18: =IF('Zoopl Count'!K18="","",'Zoopl Count'!K18*(2^K$9)/K$8) | L18: =IF('Zoopl Count'!L18="","",'Zoopl Count'!L18*(2^L$9)/L$8) | M18: =IF('Zoopl Count'!M18="","",'Zoopl Count'!M18*(2^M$9)/M$8) | N18: =IF('Zoopl Count'!N18="","",'Zoopl Count'!N18*(2^N$9)/N$8) | ... P18: =IF('Zoopl Count'!P18="","",'Zoopl Count'!P18*(2^P$9)/P$8)
D19: Family: | E19: Orbulininae | G19: =IF('Zoopl Count'!G19="","",'Zoopl Count'!G19*(2^G$9)/G$8) | H19: =IF('Zoopl Count'!H19="","",'Zoopl Count'!H19*(2^H$9)/H$8) | I19: =IF('Zoopl Count'!I19="","",'Zoopl Count'!I19*(2^I$9)/I$8) | J19: =IF('Zoopl Count'!J19="","",'Zoopl Count'!J19*(2^J$9)/J$8) | K19: =IF('Zoopl Count'!K19="","",'Zoopl Count'!K19*(2^K$9)/K$8) | L19: =IF('Zoopl Count'!L19="","",'Zoopl Count'!L19*(2^L$9)/L$8) | M19: =IF('Zoopl Count'!M19="","",'Zoopl Count'!M19*(2^M$9)/M$8) | N19: =IF('Zoopl Count'!N19="","",'Zoopl Count'!N19*(2^N$9)/N$8) | ... P19: =IF('Zoopl Count'!P19="","",'Zoopl Count'!P19*(2^P$9)/P$8)
E20: Genus: | F20: Orbulina | G20: =IF('Zoopl Count'!G20="","",'Zoopl Count'!G20*(2^G$9)/G$8) | H20: =IF('Zoopl Count'!H20="","",'Zoopl Count'!H20*(2^H$9)/H$8) | I20: =IF('Zoopl Count'!I20="","",'Zoopl Count'!I20*(2^I$9)/I$8) | J20: =IF('Zoopl Count'!J20="","",'Zoopl Count'!J20*(2^J$9)/J$8) | K20: =IF('Zoopl Count'!K20="","",'Zoopl Count'!K20*(2^K$9)/K$8) | L20: =IF('Zoopl Count'!L20="","",'Zoopl Count'!L20*(2^L$9)/L$8) | M20: =IF('Zoopl Count'!M20="","",'Zoopl Count'!M20*(2^M$9)/M$8) | N20: =IF('Zoopl Count'!N20="","",'Zoopl Count'!N20*(2^N$9)/N$8) | ... P20: =IF('Zoopl Count'!P20="","",'Zoopl Count'!P20*(2^P$9)/P$8)
D21: Family: | E21: Calcarinidae | G21: =IF('Zoopl Count'!G21="","",'Zoopl Count'!G21*(2^G$9)/G$8) | H21: =IF('Zoopl Count'!H21="","",'Zoopl Count'!H21*(2^H$9)/H$8) | I21: =IF('Zoopl Count'!I21="","",'Zoopl Count'!I21*(2^I$9)/I$8) | J21: =IF('Zoopl Count'!J21="","",'Zoopl Count'!J21*(2^J$9)/J$8) | K21: =IF('Zoopl Count'!K21="","",'Zoopl Count'!K21*(2^K$9)/K$8) | L21: =IF('Zoopl Count'!L21="","",'Zoopl Count'!L21*(2^L$9)/L$8) | M21: =IF('Zoopl Count'!M21="","",'Zoopl Count'!M21*(2^M$9)/M$8) | N21: =IF('Zoopl Count'!N21="","",'Zoopl Count'!N21*(2^N$9)/N$8) | ... P21: =IF('Zoopl Count'!P21="","",'Zoopl Count'!P21*(2^P$9)/P$8)
E22: Genus: | F22: Baculogypsina | G22: =IF('Zoopl Count'!G22="","",'Zoopl Count'!G22*(2^G$9)/G$8) | H22: =IF('Zoopl Count'!H22="","",'Zoopl Count'!H22*(2^H$9)/H$8) | I22: =IF('Zoopl Count'!I22="","",'Zoopl Count'!I22*(2^I$9)/I$8) | J22: =IF('Zoopl Count'!J22="","",'Zoopl Count'!J22*(2^J$9)/J$8) | K22: =IF('Zoopl Count'!K22="","",'Zoopl Count'!K22*(2^K$9)/K$8) | L22: =IF('Zoopl Count'!L22="","",'Zoopl Count'!L22*(2^L$9)/L$8) | M22: =IF('Zoopl Count'!M22="","",'Zoopl Count'!M22*(2^M$9)/M$8) | N22: =IF('Zoopl Count'!N22="","",'Zoopl Count'!N22*(2^N$9)/N$8) | ... P22: =IF('Zoopl Count'!P22="","",'Zoopl Count'!P22*(2^P$9)/P$8)
G23: =IF('Zoopl Count'!G23="","",'Zoopl Count'!G23*(2^G$9)/G$8) | H23: =IF('Zoopl Count'!H23="","",'Zoopl Count'!H23*(2^H$9)/H$8) | I23: =IF('Zoopl Count'!I23="","",'Zoopl Count'!I23*(2^I$9)/I$8) | J23: =IF('Zoopl Count'!J23="","",'Zoopl Count'!J23*(2^J$9)/J$8) | K23: =IF('Zoopl Count'!K23="","",'Zoopl Count'!K23*(2^K$9)/K$8) | L23: =IF('Zoopl Count'!L23="","",'Zoopl Count'!L23*(2^L$9)/L$8) | M23: =IF('Zoopl Count'!M23="","",'Zoopl Count'!M23*(2^M$9)/M$8) | N23: =IF('Zoopl Count'!N23="","",'Zoopl Count'!N23*(2^N$9)/N$8) | ... P23: =IF('Zoopl Count'!P23="","",'Zoopl Count'!P23*(2^P$9)/P$8)
B24: Class: | C24: Tubothalamea | G24: =IF('Zoopl Count'!G24="","",'Zoopl Count'!G24*(2^G$9)/G$8) | H24: =IF('Zoopl Count'!H24="","",'Zoopl Count'!H24*(2^H$9)/H$8) | I24: =IF('Zoopl Count'!I24="","",'Zoopl Count'!I24*(2^I$9)/I$8) | J24: =IF('Zoopl Count'!J24="","",'Zoopl Count'!J24*(2^J$9)/J$8) | K24: =IF('Zoopl Count'!K24="","",'Zoopl Count'!K24*(2^K$9)/K$8) | L24: =IF('Zoopl Count'!L24="","",'Zoopl Count'!L24*(2^L$9)/L$8) | M24: =IF('Zoopl Count'!M24="","",'Zoopl Count'!M24*(2^M$9)/M$8) | N24: =IF('Zoopl Count'!N24="","",'Zoopl Count'!N24*(2^N$9)/N$8) | ... P24: =IF('Zoopl Count'!P24="","",'Zoopl Count'!P24*(2^P$9)/P$8)
C25: Order: | D25: Miliolida | G25: =IF('Zoopl Count'!G25="","",'Zoopl Count'!G25*(2^G$9)/G$8) | H25: =IF('Zoopl Count'!H25="","",'Zoopl Count'!H25*(2^H$9)/H$8) | I25: =IF('Zoopl Count'!I25="","",'Zoopl Count'!I25*(2^I$9)/I$8) | J25: =IF('Zoopl Count'!J25="","",'Zoopl Count'!J25*(2^J$9)/J$8) | K25: =IF('Zoopl Count'!K25="","",'Zoopl Count'!K25*(2^K$9)/K$8) | L25: =IF('Zoopl Count'!L25="","",'Zoopl Count'!L25*(2^L$9)/L$8) | M25: =IF('Zoopl Count'!M25="","",'Zoopl Count'!M25*(2^M$9)/M$8) | N25: =IF('Zoopl Count'!N25="","",'Zoopl Count'!N25*(2^N$9)/N$8) | ... P25: =IF('Zoopl Count'!P25="","",'Zoopl Count'!P25*(2^P$9)/P$8)
D26: Family: | E26: Spiroloculinidae | G26: =IF('Zoopl Count'!G26="","",'Zoopl Count'!G26*(2^G$9)/G$8) | H26: =IF('Zoopl Count'!H26="","",'Zoopl Count'!H26*(2^H$9)/H$8) | I26: =IF('Zoopl Count'!I26="","",'Zoopl Count'!I26*(2^I$9)/I$8) | J26: =IF('Zoopl Count'!J26="","",'Zoopl Count'!J26*(2^J$9)/J$8) | K26: =IF('Zoopl Count'!K26="","",'Zoopl Count'!K26*(2^K$9)/K$8) | L26: =IF('Zoopl Count'!L26="","",'Zoopl Count'!L26*(2^L$9)/L$8) | M26: =IF('Zoopl Count'!M26="","",'Zoopl Count'!M26*(2^M$9)/M$8) | N26: =IF('Zoopl Count'!N26="","",'Zoopl Count'!N26*(2^N$9)/N$8) | ... P26: =IF('Zoopl Count'!P26="","",'Zoopl Count'!P26*(2^P$9)/P$8)
E27: Genus: | F27: Spiroloculina | G27: =IF('Zoopl Count'!G27="","",'Zoopl Count'!G27*(2^G$9)/G$8) | H27: =IF('Zoopl Count'!H27="","",'Zoopl Count'!H27*(2^H$9)/H$8) | I27: =IF('Zoopl Count'!I27="","",'Zoopl Count'!I27*(2^I$9)/I$8) | J27: =IF('Zoopl Count'!J27="","",'Zoopl Count'!J27*(2^J$9)/J$8) | K27: =IF('Zoopl Count'!K27="","",'Zoopl Count'!K27*(2^K$9)/K$8) | L27: =IF('Zoopl Count'!L27="","",'Zoopl Count'!L27*(2^L$9)/L$8) | M27: =IF('Zoopl Count'!M27="","",'Zoopl Count'!M27*(2^M$9)/M$8) | N27: =IF('Zoopl Count'!N27="","",'Zoopl Count'!N27*(2^N$9)/N$8) | ... P27: =IF('Zoopl Count'!P27="","",'Zoopl Count'!P27*(2^P$9)/P$8)
G28: =IF('Zoopl Count'!G28="","",'Zoopl Count'!G28*(2^G$9)/G$8) | H28: =IF('Zoopl Count'!H28="","",'Zoopl Count'!H28*(2^H$9)/H$8) | I28: =IF('Zoopl Count'!I28="","",'Zoopl Count'!I28*(2^I$9)/I$8) | J28: =IF('Zoopl Count'!J28="","",'Zoopl Count'!J28*(2^J$9)/J$8) | K28: =IF('Zoopl Count'!K28="","",'Zoopl Count'!K28*(2^K$9)/K$8) | L28: =IF('Zoopl Count'!L28="","",'Zoopl Count'!L28*(2^L$9)/L$8) | M28: =IF('Zoopl Count'!M28="","",'Zoopl Count'!M28*(2^M$9)/M$8) | N28: =IF('Zoopl Count'!N28="","",'Zoopl Count'!N28*(2^N$9)/N$8) | ... P28: =IF('Zoopl Count'!P28="","",'Zoopl Count'!P28*(2^P$9)/P$8)
B29: Class: | C29: Nodosariata | G29: =IF('Zoopl Count'!G29="","",'Zoopl Count'!G29*(2^G$9)/G$8) | H29: =IF('Zoopl Count'!H29="","",'Zoopl Count'!H29*(2^H$9)/H$8) | I29: =IF('Zoopl Count'!I29="","",'Zoopl Count'!I29*(2^I$9)/I$8) | J29: =IF('Zoopl Count'!J29="","",'Zoopl Count'!J29*(2^J$9)/J$8) | K29: =IF('Zoopl Count'!K29="","",'Zoopl Count'!K29*(2^K$9)/K$8) | L29: =IF('Zoopl Count'!L29="","",'Zoopl Count'!L29*(2^L$9)/L$8) | M29: =IF('Zoopl Count'!M29="","",'Zoopl Count'!M29*(2^M$9)/M$8) | N29: =IF('Zoopl Count'!N29="","",'Zoopl Count'!N29*(2^N$9)/N$8) | ... P29: =IF('Zoopl Count'!P29="","",'Zoopl Count'!P29*(2^P$9)/P$8)
C30: Order: | D30: Vaginulida | G30: =IF('Zoopl Count'!G30="","",'Zoopl Count'!G30*(2^G$9)/G$8) | H30: =IF('Zoopl Count'!H30="","",'Zoopl Count'!H30*(2^H$9)/H$8) | I30: =IF('Zoopl Count'!I30="","",'Zoopl Count'!I30*(2^I$9)/I$8) | J30: =IF('Zoopl Count'!J30="","",'Zoopl Count'!J30*(2^J$9)/J$8) | K30: =IF('Zoopl Count'!K30="","",'Zoopl Count'!K30*(2^K$9)/K$8) | L30: =IF('Zoopl Count'!L30="","",'Zoopl Count'!L30*(2^L$9)/L$8) | M30: =IF('Zoopl Count'!M30="","",'Zoopl Count'!M30*(2^M$9)/M$8) | N30: =IF('Zoopl Count'!N30="","",'Zoopl Count'!N30*(2^N$9)/N$8) | ... P30: =IF('Zoopl Count'!P30="","",'Zoopl Count'!P30*(2^P$9)/P$8)
D31: Family: | E31: Vaginulinidae | G31: =IF('Zoopl Count'!G31="","",'Zoopl Count'!G31*(2^G$9)/G$8) | H31: =IF('Zoopl Count'!H31="","",'Zoopl Count'!H31*(2^H$9)/H$8) | I31: =IF('Zoopl Count'!I31="","",'Zoopl Count'!I31*(2^I$9)/I$8) | J31: =IF('Zoopl Count'!J31="","",'Zoopl Count'!J31*(2^J$9)/J$8) | K31: =IF('Zoopl Count'!K31="","",'Zoopl Count'!K31*(2^K$9)/K$8) | L31: =IF('Zoopl Count'!L31="","",'Zoopl Count'!L31*(2^L$9)/L$8) | M31: =IF('Zoopl Count'!M31="","",'Zoopl Count'!M31*(2^M$9)/M$8) | N31: =IF('Zoopl Count'!N31="","",'Zoopl Count'!N31*(2^N$9)/N$8) | ... P31: =IF('Zoopl Count'!P31="","",'Zoopl Count'!P31*(2^P$9)/P$8)
E32: Genus: | F32: Planularia | G32: =IF('Zoopl Count'!G32="","",'Zoopl Count'!G32*(2^G$9)/G$8) | H32: =IF('Zoopl Count'!H32="","",'Zoopl Count'!H32*(2^H$9)/H$8) | I32: =IF('Zoopl Count'!I32="","",'Zoopl Count'!I32*(2^I$9)/I$8) | J32: =IF('Zoopl Count'!J32="","",'Zoopl Count'!J32*(2^J$9)/J$8) | K32: =IF('Zoopl Count'!K32="","",'Zoopl Count'!K32*(2^K$9)/K$8) | L32: =IF('Zoopl Count'!L32="","",'Zoopl Count'!L32*(2^L$9)/L$8) | M32: =IF('Zoopl Count'!M32="","",'Zoopl Count'!M32*(2^M$9)/M$8) | N32: =IF('Zoopl Count'!N32="","",'Zoopl Count'!N32*(2^N$9)/N$8) | ... P32: =IF('Zoopl Count'!P32="","",'Zoopl Count'!P32*(2^P$9)/P$8)
F33: Lenticulina | G33: =IF('Zoopl Count'!G33="","",'Zoopl Count'!G33*(2^G$9)/G$8) | H33: =IF('Zoopl Count'!H33="","",'Zoopl Count'!H33*(2^H$9)/H$8) | I33: =IF('Zoopl Count'!I33="","",'Zoopl Count'!I33*(2^I$9)/I$8) | J33: =IF('Zoopl Count'!J33="","",'Zoopl Count'!J33*(2^J$9)/J$8) | K33: =IF('Zoopl Count'!K33="","",'Zoopl Count'!K33*(2^K$9)/K$8) | L33: =IF('Zoopl Count'!L33="","",'Zoopl Count'!L33*(2^L$9)/L$8) | M33: =IF('Zoopl Count'!M33="","",'Zoopl Count'!M33*(2^M$9)/M$8) | N33: =IF('Zoopl Count'!N33="","",'Zoopl Count'!N33*(2^N$9)/N$8) | ... P33: =IF('Zoopl Count'!P33="","",'Zoopl Count'!P33*(2^P$9)/P$8)
F34: Vaginulina | G34: =IF('Zoopl Count'!G34="","",'Zoopl Count'!G34*(2^G$9)/G$8) | H34: =IF('Zoopl Count'!H34="","",'Zoopl Count'!H34*(2^H$9)/H$8) | I34: =IF('Zoopl Count'!I34="","",'Zoopl Count'!I34*(2^I$9)/I$8) | J34: =IF('Zoopl Count'!J34="","",'Zoopl Count'!J34*(2^J$9)/J$8) | K34: =IF('Zoopl Count'!K34="","",'Zoopl Count'!K34*(2^K$9)/K$8) | L34: =IF('Zoopl Count'!L34="","",'Zoopl Count'!L34*(2^L$9)/L$8) | M34: =IF('Zoopl Count'!M34="","",'Zoopl Count'!M34*(2^M$9)/M$8) | N34: =IF('Zoopl Count'!N34="","",'Zoopl Count'!N34*(2^N$9)/N$8) | ... P34: =IF('Zoopl Count'!P34="","",'Zoopl Count'!P34*(2^P$9)/P$8)
G35: =IF('Zoopl Count'!G35="","",'Zoopl Count'!G35*(2^G$9)/G$8) | H35: =IF('Zoopl Count'!H35="","",'Zoopl Count'!H35*(2^H$9)/H$8) | I35: =IF('Zoopl Count'!I35="","",'Zoopl Count'!I35*(2^I$9)/I$8) | J35: =IF('Zoopl Count'!J35="","",'Zoopl Count'!J35*(2^J$9)/J$8) | K35: =IF('Zoopl Count'!K35="","",'Zoopl Count'!K35*(2^K$9)/K$8) | L35: =IF('Zoopl Count'!L35="","",'Zoopl Count'!L35*(2^L$9)/L$8) | M35: =IF('Zoopl Count'!M35="","",'Zoopl Count'!M35*(2^M$9)/M$8) | N35: =IF('Zoopl Count'!N35="","",'Zoopl Count'!N35*(2^N$9)/N$8) | ... P35: =IF('Zoopl Count'!P35="","",'Zoopl Count'!P35*(2^P$9)/P$8)
A36: Phylum: | B36: Radiozoa | G36: =IF('Zoopl Count'!G36="","",'Zoopl Count'!G36*(2^G$9)/G$8) | H36: =IF('Zoopl Count'!H36="","",'Zoopl Count'!H36*(2^H$9)/H$8) | I36: =IF('Zoopl Count'!I36="","",'Zoopl Count'!I36*(2^I$9)/I$8) | J36: =IF('Zoopl Count'!J36="","",'Zoopl Count'!J36*(2^J$9)/J$8) | K36: =IF('Zoopl Count'!K36="","",'Zoopl Count'!K36*(2^K$9)/K$8) | L36: =IF('Zoopl Count'!L36="","",'Zoopl Count'!L36*(2^L$9)/L$8) | M36: =IF('Zoopl Count'!M36="","",'Zoopl Count'!M36*(2^M$9)/M$8) | N36: =IF('Zoopl Count'!N36="","",'Zoopl Count'!N36*(2^N$9)/N$8) | ... P36: =IF('Zoopl Count'!P36="","",'Zoopl Count'!P36*(2^P$9)/P$8)
B37: Class: | C37: Acantharia | G37: =IF('Zoopl Count'!G37="","",'Zoopl Count'!G37*(2^G$9)/G$8) | H37: =IF('Zoopl Count'!H37="","",'Zoopl Count'!H37*(2^H$9)/H$8) | I37: =IF('Zoopl Count'!I37="","",'Zoopl Count'!I37*(2^I$9)/I$8) | J37: =IF('Zoopl Count'!J37="","",'Zoopl Count'!J37*(2^J$9)/J$8) | K37: =IF('Zoopl Count'!K37="","",'Zoopl Count'!K37*(2^K$9)/K$8) | L37: =IF('Zoopl Count'!L37="","",'Zoopl Count'!L37*(2^L$9)/L$8) | M37: =IF('Zoopl Count'!M37="","",'Zoopl Count'!M37*(2^M$9)/M$8) | N37: =IF('Zoopl Count'!N37="","",'Zoopl Count'!N37*(2^N$9)/N$8) | ... P37: =IF('Zoopl Count'!P37="","",'Zoopl Count'!P37*(2^P$9)/P$8)
C38: Order: | D38: Arthracanthida | G38: =IF('Zoopl Count'!G38="","",'Zoopl Count'!G38*(2^G$9)/G$8) | H38: =IF('Zoopl Count'!H38="","",'Zoopl Count'!H38*(2^H$9)/H$8) | I38: =IF('Zoopl Count'!I38="","",'Zoopl Count'!I38*(2^I$9)/I$8) | J38: =IF('Zoopl Count'!J38="","",'Zoopl Count'!J38*(2^J$9)/J$8) | K38: =IF('Zoopl Count'!K38="","",'Zoopl Count'!K38*(2^K$9)/K$8) | L38: =IF('Zoopl Count'!L38="","",'Zoopl Count'!L38*(2^L$9)/L$8) | M38: =IF('Zoopl Count'!M38="","",'Zoopl Count'!M38*(2^M$9)/M$8) | N38: =IF('Zoopl Count'!N38="","",'Zoopl Count'!N38*(2^N$9)/N$8) | ... P38: =IF('Zoopl Count'!P38="","",'Zoopl Count'!P38*(2^P$9)/P$8)
D39: Family: | E39: Acanthometridae | G39: =IF('Zoopl Count'!G39="","",'Zoopl Count'!G39*(2^G$9)/G$8) | H39: =IF('Zoopl Count'!H39="","",'Zoopl Count'!H39*(2^H$9)/H$8) | I39: =IF('Zoopl Count'!I39="","",'Zoopl Count'!I39*(2^I$9)/I$8) | J39: =IF('Zoopl Count'!J39="","",'Zoopl Count'!J39*(2^J$9)/J$8) | K39: =IF('Zoopl Count'!K39="","",'Zoopl Count'!K39*(2^K$9)/K$8) | L39: =IF('Zoopl Count'!L39="","",'Zoopl Count'!L39*(2^L$9)/L$8) | M39: =IF('Zoopl Count'!M39="","",'Zoopl Count'!M39*(2^M$9)/M$8) | N39: =IF('Zoopl Count'!N39="","",'Zoopl Count'!N39*(2^N$9)/N$8) | ... P39: =IF('Zoopl Count'!P39="","",'Zoopl Count'!P39*(2^P$9)/P$8)
E40: Genus: | F40: Acanthometron | G40: =IF('Zoopl Count'!G40="","",'Zoopl Count'!G40*(2^G$9)/G$8) | H40: =IF('Zoopl Count'!H40="","",'Zoopl Count'!H40*(2^H$9)/H$8) | I40: =IF('Zoopl Count'!I40="","",'Zoopl Count'!I40*(2^I$9)/I$8) | J40: =IF('Zoopl Count'!J40="","",'Zoopl Count'!J40*(2^J$9)/J$8) | K40: =IF('Zoopl Count'!K40="","",'Zoopl Count'!K40*(2^K$9)/K$8) | L40: =IF('Zoopl Count'!L40="","",'Zoopl Count'!L40*(2^L$9)/L$8) | M40: =IF('Zoopl Count'!M40="","",'Zoopl Count'!M40*(2^M$9)/M$8) | N40: =IF('Zoopl Count'!N40="","",'Zoopl Count'!N40*(2^N$9)/N$8) | ... P40: =IF('Zoopl Count'!P40="","",'Zoopl Count'!P40*(2^P$9)/P$8)
G41: =IF('Zoopl Count'!G41="","",'Zoopl Count'!G41*(2^G$9)/G$8) | H41: =IF('Zoopl Count'!H41="","",'Zoopl Count'!H41*(2^H$9)/H$8) | I41: =IF('Zoopl Count'!I41="","",'Zoopl Count'!I41*(2^I$9)/I$8) | J41: =IF('Zoopl Count'!J41="","",'Zoopl Count'!J41*(2^J$9)/J$8) | K41: =IF('Zoopl Count'!K41="","",'Zoopl Count'!K41*(2^K$9)/K$8) | L41: =IF('Zoopl Count'!L41="","",'Zoopl Count'!L41*(2^L$9)/L$8) | M41: =IF('Zoopl Count'!M41="","",'Zoopl Count'!M41*(2^M$9)/M$8) | N41: =IF('Zoopl Count'!N41="","",'Zoopl Count'!N41*(2^N$9)/N$8) | ... P41: =IF('Zoopl Count'!P41="","",'Zoopl Count'!P41*(2^P$9)/P$8)
G42: =IF('Zoopl Count'!G42="","",'Zoopl Count'!G42*(2^G$9)/G$8) | H42: =IF('Zoopl Count'!H42="","",'Zoopl Count'!H42*(2^H$9)/H$8) | I42: =IF('Zoopl Count'!I42="","",'Zoopl Count'!I42*(2^I$9)/I$8) | J42: =IF('Zoopl Count'!J42="","",'Zoopl Count'!J42*(2^J$9)/J$8) | K42: =IF('Zoopl Count'!K42="","",'Zoopl Count'!K42*(2^K$9)/K$8) | L42: =IF('Zoopl Count'!L42="","",'Zoopl Count'!L42*(2^L$9)/L$8) | M42: =IF('Zoopl Count'!M42="","",'Zoopl Count'!M42*(2^M$9)/M$8) | N42: =IF('Zoopl Count'!N42="","",'Zoopl Count'!N42*(2^N$9)/N$8) | ... P42: =IF('Zoopl Count'!P42="","",'Zoopl Count'!P42*(2^P$9)/P$8)
...

Sheet LN Data
A1: Log(n) of Zooplankton data for Diversity calculations
F7: ='Zoopl Count'!F4 -> Sample Marking: | G7: ='Zoopl Count'!G4 -> PLW-25-274014-1 | H7: ='Zoopl Count'!H4 -> PLW-25-274014-2 | I7: ='Zoopl Count'!I4 -> PLW-25-274014-3 | J7: ='Zoopl Count'!J4 -> PLW-25-274014-4 | K7: ='Zoopl Count'!K4 -> PLW-25-274014-5 | L7: ='Zoopl Count'!L4 -> PLW-25-274016-1 | M7: ='Zoopl Count'!M4 -> PLW-25-274016-2 | ... P7: ='Zoopl Count'!P4 -> PLW-25-274016-5
F8: ='Zoopl Count'!F8 -> Volume filtered (l): | G8: ='Zoopl Count'!G8 -> 245.43693 | H8: ='Zoopl Count'!H8 -> 245.43693 | I8: ='Zoopl Count'!I8 -> 245.43693 | J8: ='Zoopl Count'!J8 -> 245.43693 | K8: ='Zoopl Count'!K8 -> 245.43693 | L8: ='Zoopl Count'!L8 -> 245.43693 | M8: ='Zoopl Count'!M8 -> 245.43693 | ... P8: ='Zoopl Count'!P8 -> 245.43693
F9: ='Zoopl Count'!F9 -> Split factor: | G9: ='Zoopl Count'!G9 -> 5 | H9: ='Zoopl Count'!H9 -> 4 | I9: ='Zoopl Count'!I9 -> 3 | J9: ='Zoopl Count'!J9 -> 5 | K9: ='Zoopl Count'!K9 -> 5 | L9: ='Zoopl Count'!L9 -> 7 | M9: ='Zoopl Count'!M9 -> 5 | ... P9: ='Zoopl Count'!P9 -> 5
A10: Phylum: | B10: Foraminifera | G10: =IF('Zoopl Count'!G10=0,"",('Zoopl Analysis'!G10*LN('Zoopl Analysis'!G10))) | H10: =IF('Zoopl Count'!H10=0,"",('Zoopl Analysis'!H10*LN('Zoopl Analysis'!H10))) | I10: =IF('Zoopl Count'!I10=0,"",('Zoopl Analysis'!I10*LN('Zoopl Analysis'!I10))) | J10: =IF('Zoopl Count'!J10=0,"",('Zoopl Analysis'!J10*LN('Zoopl Analysis'!J10))) | K10: =IF('Zoopl Count'!K10=0,"",('Zoopl Analysis'!K10*LN('Zoopl Analysis'!K10))) | L10: =IF('Zoopl Count'!L10=0,"",('Zoopl Analysis'!L10*LN('Zoopl Analysis'!L10))) | M10: =IF('Zoopl Count'!M10=0,"",('Zoopl Analysis'!M10*LN('Zoopl Analysis'!M10))) | N10: =IF('Zoopl Count'!N10=0,"",('Zoopl Analysis'!N10*LN('Zoopl Analysis'!N10))) | ... P10: =IF('Zoopl Count'!P10=0,"",('Zoopl Analysis'!P10*LN('Zoopl Analysis'!P10)))
B11: Class: | C11: Globothalamea | G11: =IF('Zoopl Count'!G11=0,"",('Zoopl Analysis'!G11*LN('Zoopl Analysis'!G11))) | H11: =IF('Zoopl Count'!H11=0,"",('Zoopl Analysis'!H11*LN('Zoopl Analysis'!H11))) | I11: =IF('Zoopl Count'!I11=0,"",('Zoopl Analysis'!I11*LN('Zoopl Analysis'!I11))) | J11: =IF('Zoopl Count'!J11=0,"",('Zoopl Analysis'!J11*LN('Zoopl Analysis'!J11))) | K11: =IF('Zoopl Count'!K11=0,"",('Zoopl Analysis'!K11*LN('Zoopl Analysis'!K11))) | L11: =IF('Zoopl Count'!L11=0,"",('Zoopl Analysis'!L11*LN('Zoopl Analysis'!L11))) | M11: =IF('Zoopl Count'!M11=0,"",('Zoopl Analysis'!M11*LN('Zoopl Analysis'!M11))) | N11: =IF('Zoopl Count'!N11=0,"",('Zoopl Analysis'!N11*LN('Zoopl Analysis'!N11))) | ... P11: =IF('Zoopl Count'!P11=0,"",('Zoopl Analysis'!P11*LN('Zoopl Analysis'!P11)))
C12: Order: | D12: Rotaliida | G12: =IF('Zoopl Count'!G12=0,"",('Zoopl Analysis'!G12*LN('Zoopl Analysis'!G12))) | H12: =IF('Zoopl Count'!H12=0,"",('Zoopl Analysis'!H12*LN('Zoopl Analysis'!H12))) | I12: =IF('Zoopl Count'!I12=0,"",('Zoopl Analysis'!I12*LN('Zoopl Analysis'!I12))) | J12: =IF('Zoopl Count'!J12=0,"",('Zoopl Analysis'!J12*LN('Zoopl Analysis'!J12))) | K12: =IF('Zoopl Count'!K12=0,"",('Zoopl Analysis'!K12*LN('Zoopl Analysis'!K12))) | L12: =IF('Zoopl Count'!L12=0,"",('Zoopl Analysis'!L12*LN('Zoopl Analysis'!L12))) | M12: =IF('Zoopl Count'!M12=0,"",('Zoopl Analysis'!M12*LN('Zoopl Analysis'!M12))) | N12: =IF('Zoopl Count'!N12=0,"",('Zoopl Analysis'!N12*LN('Zoopl Analysis'!N12))) | ... P12: =IF('Zoopl Count'!P12=0,"",('Zoopl Analysis'!P12*LN('Zoopl Analysis'!P12)))
D13: Family: | E13: Bolivinitidae | G13: =IF('Zoopl Count'!G13=0,"",('Zoopl Analysis'!G13*LN('Zoopl Analysis'!G13))) | H13: =IF('Zoopl Count'!H13=0,"",('Zoopl Analysis'!H13*LN('Zoopl Analysis'!H13))) | I13: =IF('Zoopl Count'!I13=0,"",('Zoopl Analysis'!I13*LN('Zoopl Analysis'!I13))) | J13: =IF('Zoopl Count'!J13=0,"",('Zoopl Analysis'!J13*LN('Zoopl Analysis'!J13))) | K13: =IF('Zoopl Count'!K13=0,"",('Zoopl Analysis'!K13*LN('Zoopl Analysis'!K13))) | L13: =IF('Zoopl Count'!L13=0,"",('Zoopl Analysis'!L13*LN('Zoopl Analysis'!L13))) | M13: =IF('Zoopl Count'!M13=0,"",('Zoopl Analysis'!M13*LN('Zoopl Analysis'!M13))) | N13: =IF('Zoopl Count'!N13=0,"",('Zoopl Analysis'!N13*LN('Zoopl Analysis'!N13))) | ... P13: =IF('Zoopl Count'!P13=0,"",('Zoopl Analysis'!P13*LN('Zoopl Analysis'!P13)))
E14: Genus: | F14: Bolivina | G14: =IF('Zoopl Count'!G14=0,"",('Zoopl Analysis'!G14*LN('Zoopl Analysis'!G14))) | H14: =IF('Zoopl Count'!H14=0,"",('Zoopl Analysis'!H14*LN('Zoopl Analysis'!H14))) | I14: =IF('Zoopl Count'!I14=0,"",('Zoopl Analysis'!I14*LN('Zoopl Analysis'!I14))) | J14: =IF('Zoopl Count'!J14=0,"",('Zoopl Analysis'!J14*LN('Zoopl Analysis'!J14))) | K14: =IF('Zoopl Count'!K14=0,"",('Zoopl Analysis'!K14*LN('Zoopl Analysis'!K14))) | L14: =IF('Zoopl Count'!L14=0,"",('Zoopl Analysis'!L14*LN('Zoopl Analysis'!L14))) | M14: =IF('Zoopl Count'!M14=0,"",('Zoopl Analysis'!M14*LN('Zoopl Analysis'!M14))) | N14: =IF('Zoopl Count'!N14=0,"",('Zoopl Analysis'!N14*LN('Zoopl Analysis'!N14))) | ... P14: =IF('Zoopl Count'!P14=0,"",('Zoopl Analysis'!P14*LN('Zoopl Analysis'!P14)))
D15: Family: | E15: Globigerinidae | G15: =IF('Zoopl Count'!G15=0,"",('Zoopl Analysis'!G15*LN('Zoopl Analysis'!G15))) | H15: =IF('Zoopl Count'!H15=0,"",('Zoopl Analysis'!H15*LN('Zoopl Analysis'!H15))) | I15: =IF('Zoopl Count'!I15=0,"",('Zoopl Analysis'!I15*LN('Zoopl Analysis'!I15))) | J15: =IF('Zoopl Count'!J15=0,"",('Zoopl Analysis'!J15*LN('Zoopl Analysis'!J15))) | K15: =IF('Zoopl Count'!K15=0,"",('Zoopl Analysis'!K15*LN('Zoopl Analysis'!K15))) | L15: =IF('Zoopl Count'!L15=0,"",('Zoopl Analysis'!L15*LN('Zoopl Analysis'!L15))) | M15: =IF('Zoopl Count'!M15=0,"",('Zoopl Analysis'!M15*LN('Zoopl Analysis'!M15))) | N15: =IF('Zoopl Count'!N15=0,"",('Zoopl Analysis'!N15*LN('Zoopl Analysis'!N15))) | ... P15: =IF('Zoopl Count'!P15=0,"",('Zoopl Analysis'!P15*LN('Zoopl Analysis'!P15)))
E16: Genus: | F16: Globigerina | G16: =IF('Zoopl Count'!G16=0,"",('Zoopl Analysis'!G16*LN('Zoopl Analysis'!G16))) | H16: =IF('Zoopl Count'!H16=0,"",('Zoopl Analysis'!H16*LN('Zoopl Analysis'!H16))) | I16: =IF('Zoopl Count'!I16=0,"",('Zoopl Analysis'!I16*LN('Zoopl Analysis'!I16))) | J16: =IF('Zoopl Count'!J16=0,"",('Zoopl Analysis'!J16*LN('Zoopl Analysis'!J16))) | K16: =IF('Zoopl Count'!K16=0,"",('Zoopl Analysis'!K16*LN('Zoopl Analysis'!K16))) | L16: =IF('Zoopl Count'!L16=0,"",('Zoopl Analysis'!L16*LN('Zoopl Analysis'!L16))) | M16: =IF('Zoopl Count'!M16=0,"",('Zoopl Analysis'!M16*LN('Zoopl Analysis'!M16))) | N16: =IF('Zoopl Count'!N16=0,"",('Zoopl Analysis'!N16*LN('Zoopl Analysis'!N16))) | ... P16: =IF('Zoopl Count'!P16=0,"",('Zoopl Analysis'!P16*LN('Zoopl Analysis'!P16)))
D17: Family: | E17: Globorotaliidae | G17: =IF('Zoopl Count'!G17=0,"",('Zoopl Analysis'!G17*LN('Zoopl Analysis'!G17))) | H17: =IF('Zoopl Count'!H17=0,"",('Zoopl Analysis'!H17*LN('Zoopl Analysis'!H17))) | I17: =IF('Zoopl Count'!I17=0,"",('Zoopl Analysis'!I17*LN('Zoopl Analysis'!I17))) | J17: =IF('Zoopl Count'!J17=0,"",('Zoopl Analysis'!J17*LN('Zoopl Analysis'!J17))) | K17: =IF('Zoopl Count'!K17=0,"",('Zoopl Analysis'!K17*LN('Zoopl Analysis'!K17))) | L17: =IF('Zoopl Count'!L17=0,"",('Zoopl Analysis'!L17*LN('Zoopl Analysis'!L17))) | M17: =IF('Zoopl Count'!M17=0,"",('Zoopl Analysis'!M17*LN('Zoopl Analysis'!M17))) | N17: =IF('Zoopl Count'!N17=0,"",('Zoopl Analysis'!N17*LN('Zoopl Analysis'!N17))) | ... P17: =IF('Zoopl Count'!P17=0,"",('Zoopl Analysis'!P17*LN('Zoopl Analysis'!P17)))
E18: Genus: | F18: Globorotalia | G18: =IF('Zoopl Count'!G18=0,"",('Zoopl Analysis'!G18*LN('Zoopl Analysis'!G18))) | H18: =IF('Zoopl Count'!H18=0,"",('Zoopl Analysis'!H18*LN('Zoopl Analysis'!H18))) | I18: =IF('Zoopl Count'!I18=0,"",('Zoopl Analysis'!I18*LN('Zoopl Analysis'!I18))) | J18: =IF('Zoopl Count'!J18=0,"",('Zoopl Analysis'!J18*LN('Zoopl Analysis'!J18))) | K18: =IF('Zoopl Count'!K18=0,"",('Zoopl Analysis'!K18*LN('Zoopl Analysis'!K18))) | L18: =IF('Zoopl Count'!L18=0,"",('Zoopl Analysis'!L18*LN('Zoopl Analysis'!L18))) | M18: =IF('Zoopl Count'!M18=0,"",('Zoopl Analysis'!M18*LN('Zoopl Analysis'!M18))) | N18: =IF('Zoopl Count'!N18=0,"",('Zoopl Analysis'!N18*LN('Zoopl Analysis'!N18))) | ... P18: =IF('Zoopl Count'!P18=0,"",('Zoopl Analysis'!P18*LN('Zoopl Analysis'!P18)))
D19: Family: | E19: Orbulininae | G19: =IF('Zoopl Count'!G19=0,"",('Zoopl Analysis'!G19*LN('Zoopl Analysis'!G19))) | H19: =IF('Zoopl Count'!H19=0,"",('Zoopl Analysis'!H19*LN('Zoopl Analysis'!H19))) | I19: =IF('Zoopl Count'!I19=0,"",('Zoopl Analysis'!I19*LN('Zoopl Analysis'!I19))) | J19: =IF('Zoopl Count'!J19=0,"",('Zoopl Analysis'!J19*LN('Zoopl Analysis'!J19))) | K19: =IF('Zoopl Count'!K19=0,"",('Zoopl Analysis'!K19*LN('Zoopl Analysis'!K19))) | L19: =IF('Zoopl Count'!L19=0,"",('Zoopl Analysis'!L19*LN('Zoopl Analysis'!L19))) | M19: =IF('Zoopl Count'!M19=0,"",('Zoopl Analysis'!M19*LN('Zoopl Analysis'!M19))) | N19: =IF('Zoopl Count'!N19=0,"",('Zoopl Analysis'!N19*LN('Zoopl Analysis'!N19))) | ... P19: =IF('Zoopl Count'!P19=0,"",('Zoopl Analysis'!P19*LN('Zoopl Analysis'!P19)))
E20: Genus: | F20: Orbulina | G20: =IF('Zoopl Count'!G20=0,"",('Zoopl Analysis'!G20*LN('Zoopl Analysis'!G20))) | H20: =IF('Zoopl Count'!H20=0,"",('Zoopl Analysis'!H20*LN('Zoopl Analysis'!H20))) | I20: =IF('Zoopl Count'!I20=0,"",('Zoopl Analysis'!I20*LN('Zoopl Analysis'!I20))) | J20: =IF('Zoopl Count'!J20=0,"",('Zoopl Analysis'!J20*LN('Zoopl Analysis'!J20))) | K20: =IF('Zoopl Count'!K20=0,"",('Zoopl Analysis'!K20*LN('Zoopl Analysis'!K20))) | L20: =IF('Zoopl Count'!L20=0,"",('Zoopl Analysis'!L20*LN('Zoopl Analysis'!L20))) | M20: =IF('Zoopl Count'!M20=0,"",('Zoopl Analysis'!M20*LN('Zoopl Analysis'!M20))) | N20: =IF('Zoopl Count'!N20=0,"",('Zoopl Analysis'!N20*LN('Zoopl Analysis'!N20))) | ... P20: =IF('Zoopl Count'!P20=0,"",('Zoopl Analysis'!P20*LN('Zoopl Analysis'!P20)))
D21: Family: | E21: Calcarinidae | G21: =IF('Zoopl Count'!G21=0,"",('Zoopl Analysis'!G21*LN('Zoopl Analysis'!G21))) | H21: =IF('Zoopl Count'!H21=0,"",('Zoopl Analysis'!H21*LN('Zoopl Analysis'!H21))) | I21: =IF('Zoopl Count'!I21=0,"",('Zoopl Analysis'!I21*LN('Zoopl Analysis'!I21))) | J21: =IF('Zoopl Count'!J21=0,"",('Zoopl Analysis'!J21*LN('Zoopl Analysis'!J21))) | K21: =IF('Zoopl Count'!K21=0,"",('Zoopl Analysis'!K21*LN('Zoopl Analysis'!K21))) | L21: =IF('Zoopl Count'!L21=0,"",('Zoopl Analysis'!L21*LN('Zoopl Analysis'!L21))) | M21: =IF('Zoopl Count'!M21=0,"",('Zoopl Analysis'!M21*LN('Zoopl Analysis'!M21))) | N21: =IF('Zoopl Count'!N21=0,"",('Zoopl Analysis'!N21*LN('Zoopl Analysis'!N21))) | ... P21: =IF('Zoopl Count'!P21=0,"",('Zoopl Analysis'!P21*LN('Zoopl Analysis'!P21)))
E22: Genus: | F22: Baculogypsina | G22: =IF('Zoopl Count'!G22=0,"",('Zoopl Analysis'!G22*LN('Zoopl Analysis'!G22))) | H22: =IF('Zoopl Count'!H22=0,"",('Zoopl Analysis'!H22*LN('Zoopl Analysis'!H22))) | I22: =IF('Zoopl Count'!I22=0,"",('Zoopl Analysis'!I22*LN('Zoopl Analysis'!I22))) | J22: =IF('Zoopl Count'!J22=0,"",('Zoopl Analysis'!J22*LN('Zoopl Analysis'!J22))) | K22: =IF('Zoopl Count'!K22=0,"",('Zoopl Analysis'!K22*LN('Zoopl Analysis'!K22))) | L22: =IF('Zoopl Count'!L22=0,"",('Zoopl Analysis'!L22*LN('Zoopl Analysis'!L22))) | M22: =IF('Zoopl Count'!M22=0,"",('Zoopl Analysis'!M22*LN('Zoopl Analysis'!M22))) | N22: =IF('Zoopl Count'!N22=0,"",('Zoopl Analysis'!N22*LN('Zoopl Analysis'!N22))) | ... P22: =IF('Zoopl Count'!P22=0,"",('Zoopl Analysis'!P22*LN('Zoopl Analysis'!P22)))
G23: =IF('Zoopl Count'!G23=0,"",('Zoopl Analysis'!G23*LN('Zoopl Analysis'!G23))) | H23: =IF('Zoopl Count'!H23=0,"",('Zoopl Analysis'!H23*LN('Zoopl Analysis'!H23))) | I23: =IF('Zoopl Count'!I23=0,"",('Zoopl Analysis'!I23*LN('Zoopl Analysis'!I23))) | J23: =IF('Zoopl Count'!J23=0,"",('Zoopl Analysis'!J23*LN('Zoopl Analysis'!J23))) | K23: =IF('Zoopl Count'!K23=0,"",('Zoopl Analysis'!K23*LN('Zoopl Analysis'!K23))) | L23: =IF('Zoopl Count'!L23=0,"",('Zoopl Analysis'!L23*LN('Zoopl Analysis'!L23))) | M23: =IF('Zoopl Count'!M23=0,"",('Zoopl Analysis'!M23*LN('Zoopl Analysis'!M23))) | N23: =IF('Zoopl Count'!N23=0,"",('Zoopl Analysis'!N23*LN('Zoopl Analysis'!N23))) | ... P23: =IF('Zoopl Count'!P23=0,"",('Zoopl Analysis'!P23*LN('Zoopl Analysis'!P23)))
B24: Class: | C24: Tubothalamea | G24: =IF('Zoopl Count'!G24=0,"",('Zoopl Analysis'!G24*LN('Zoopl Analysis'!G24))) | H24: =IF('Zoopl Count'!H24=0,"",('Zoopl Analysis'!H24*LN('Zoopl Analysis'!H24))) | I24: =IF('Zoopl Count'!I24=0,"",('Zoopl Analysis'!I24*LN('Zoopl Analysis'!I24))) | J24: =IF('Zoopl Count'!J24=0,"",('Zoopl Analysis'!J24*LN('Zoopl Analysis'!J24))) | K24: =IF('Zoopl Count'!K24=0,"",('Zoopl Analysis'!K24*LN('Zoopl Analysis'!K24))) | L24: =IF('Zoopl Count'!L24=0,"",('Zoopl Analysis'!L24*LN('Zoopl Analysis'!L24))) | M24: =IF('Zoopl Count'!M24=0,"",('Zoopl Analysis'!M24*LN('Zoopl Analysis'!M24))) | N24: =IF('Zoopl Count'!N24=0,"",('Zoopl Analysis'!N24*LN('Zoopl Analysis'!N24))) | ... P24: =IF('Zoopl Count'!P24=0,"",('Zoopl Analysis'!P24*LN('Zoopl Analysis'!P24)))
C25: Order: | D25: Miliolida | G25: =IF('Zoopl Count'!G25=0,"",('Zoopl Analysis'!G25*LN('Zoopl Analysis'!G25))) | H25: =IF('Zoopl Count'!H25=0,"",('Zoopl Analysis'!H25*LN('Zoopl Analysis'!H25))) | I25: =IF('Zoopl Count'!I25=0,"",('Zoopl Analysis'!I25*LN('Zoopl Analysis'!I25))) | J25: =IF('Zoopl Count'!J25=0,"",('Zoopl Analysis'!J25*LN('Zoopl Analysis'!J25))) | K25: =IF('Zoopl Count'!K25=0,"",('Zoopl Analysis'!K25*LN('Zoopl Analysis'!K25))) | L25: =IF('Zoopl Count'!L25=0,"",('Zoopl Analysis'!L25*LN('Zoopl Analysis'!L25))) | M25: =IF('Zoopl Count'!M25=0,"",('Zoopl Analysis'!M25*LN('Zoopl Analysis'!M25))) | N25: =IF('Zoopl Count'!N25=0,"",('Zoopl Analysis'!N25*LN('Zoopl Analysis'!N25))) | ... P25: =IF('Zoopl Count'!P25=0,"",('Zoopl Analysis'!P25*LN('Zoopl Analysis'!P25)))
D26: Family: | E26: Spiroloculinidae | G26: =IF('Zoopl Count'!G26=0,"",('Zoopl Analysis'!G26*LN('Zoopl Analysis'!G26))) | H26: =IF('Zoopl Count'!H26=0,"",('Zoopl Analysis'!H26*LN('Zoopl Analysis'!H26))) | I26: =IF('Zoopl Count'!I26=0,"",('Zoopl Analysis'!I26*LN('Zoopl Analysis'!I26))) | J26: =IF('Zoopl Count'!J26=0,"",('Zoopl Analysis'!J26*LN('Zoopl Analysis'!J26))) | K26: =IF('Zoopl Count'!K26=0,"",('Zoopl Analysis'!K26*LN('Zoopl Analysis'!K26))) | L26: =IF('Zoopl Count'!L26=0,"",('Zoopl Analysis'!L26*LN('Zoopl Analysis'!L26))) | M26: =IF('Zoopl Count'!M26=0,"",('Zoopl Analysis'!M26*LN('Zoopl Analysis'!M26))) | N26: =IF('Zoopl Count'!N26=0,"",('Zoopl Analysis'!N26*LN('Zoopl Analysis'!N26))) | ... P26: =IF('Zoopl Count'!P26=0,"",('Zoopl Analysis'!P26*LN('Zoopl Analysis'!P26)))
E27: Genus: | F27: Spiroloculina | G27: =IF('Zoopl Count'!G27=0,"",('Zoopl Analysis'!G27*LN('Zoopl Analysis'!G27))) | H27: =IF('Zoopl Count'!H27=0,"",('Zoopl Analysis'!H27*LN('Zoopl Analysis'!H27))) | I27: =IF('Zoopl Count'!I27=0,"",('Zoopl Analysis'!I27*LN('Zoopl Analysis'!I27))) | J27: =IF('Zoopl Count'!J27=0,"",('Zoopl Analysis'!J27*LN('Zoopl Analysis'!J27))) | K27: =IF('Zoopl Count'!K27=0,"",('Zoopl Analysis'!K27*LN('Zoopl Analysis'!K27))) | L27: =IF('Zoopl Count'!L27=0,"",('Zoopl Analysis'!L27*LN('Zoopl Analysis'!L27))) | M27: =IF('Zoopl Count'!M27=0,"",('Zoopl Analysis'!M27*LN('Zoopl Analysis'!M27))) | N27: =IF('Zoopl Count'!N27=0,"",('Zoopl Analysis'!N27*LN('Zoopl Analysis'!N27))) | ... P27: =IF('Zoopl Count'!P27=0,"",('Zoopl Analysis'!P27*LN('Zoopl Analysis'!P27)))
G28: =IF('Zoopl Count'!G28=0,"",('Zoopl Analysis'!G28*LN('Zoopl Analysis'!G28))) | H28: =IF('Zoopl Count'!H28=0,"",('Zoopl Analysis'!H28*LN('Zoopl Analysis'!H28))) | I28: =IF('Zoopl Count'!I28=0,"",('Zoopl Analysis'!I28*LN('Zoopl Analysis'!I28))) | J28: =IF('Zoopl Count'!J28=0,"",('Zoopl Analysis'!J28*LN('Zoopl Analysis'!J28))) | K28: =IF('Zoopl Count'!K28=0,"",('Zoopl Analysis'!K28*LN('Zoopl Analysis'!K28))) | L28: =IF('Zoopl Count'!L28=0,"",('Zoopl Analysis'!L28*LN('Zoopl Analysis'!L28))) | M28: =IF('Zoopl Count'!M28=0,"",('Zoopl Analysis'!M28*LN('Zoopl Analysis'!M28))) | N28: =IF('Zoopl Count'!N28=0,"",('Zoopl Analysis'!N28*LN('Zoopl Analysis'!N28))) | ... P28: =IF('Zoopl Count'!P28=0,"",('Zoopl Analysis'!P28*LN('Zoopl Analysis'!P28)))
B29: Class: | C29: Nodosariata | G29: =IF('Zoopl Count'!G29=0,"",('Zoopl Analysis'!G29*LN('Zoopl Analysis'!G29))) | H29: =IF('Zoopl Count'!H29=0,"",('Zoopl Analysis'!H29*LN('Zoopl Analysis'!H29))) | I29: =IF('Zoopl Count'!I29=0,"",('Zoopl Analysis'!I29*LN('Zoopl Analysis'!I29))) | J29: =IF('Zoopl Count'!J29=0,"",('Zoopl Analysis'!J29*LN('Zoopl Analysis'!J29))) | K29: =IF('Zoopl Count'!K29=0,"",('Zoopl Analysis'!K29*LN('Zoopl Analysis'!K29))) | L29: =IF('Zoopl Count'!L29=0,"",('Zoopl Analysis'!L29*LN('Zoopl Analysis'!L29))) | M29: =IF('Zoopl Count'!M29=0,"",('Zoopl Analysis'!M29*LN('Zoopl Analysis'!M29))) | N29: =IF('Zoopl Count'!N29=0,"",('Zoopl Analysis'!N29*LN('Zoopl Analysis'!N29))) | ... P29: =IF('Zoopl Count'!P29=0,"",('Zoopl Analysis'!P29*LN('Zoopl Analysis'!P29)))
C30: Order: | D30: Vaginulinida | G30: =IF('Zoopl Count'!G30=0,"",('Zoopl Analysis'!G30*LN('Zoopl Analysis'!G30))) | H30: =IF('Zoopl Count'!H30=0,"",('Zoopl Analysis'!H30*LN('Zoopl Analysis'!H30))) | I30: =IF('Zoopl Count'!I30=0,"",('Zoopl Analysis'!I30*LN('Zoopl Analysis'!I30))) | J30: =IF('Zoopl Count'!J30=0,"",('Zoopl Analysis'!J30*LN('Zoopl Analysis'!J30))) | K30: =IF('Zoopl Count'!K30=0,"",('Zoopl Analysis'!K30*LN('Zoopl Analysis'!K30))) | L30: =IF('Zoopl Count'!L30=0,"",('Zoopl Analysis'!L30*LN('Zoopl Analysis'!L30))) | M30: =IF('Zoopl Count'!M30=0,"",('Zoopl Analysis'!M30*LN('Zoopl Analysis'!M30))) | N30: =IF('Zoopl Count'!N30=0,"",('Zoopl Analysis'!N30*LN('Zoopl Analysis'!N30))) | ... P30: =IF('Zoopl Count'!P30=0,"",('Zoopl Analysis'!P30*LN('Zoopl Analysis'!P30)))
D31: Family: | E31: Vaginulinidae | G31: =IF('Zoopl Count'!G31=0,"",('Zoopl Analysis'!G31*LN('Zoopl Analysis'!G31))) | H31: =IF('Zoopl Count'!H31=0,"",('Zoopl Analysis'!H31*LN('Zoopl Analysis'!H31))) | I31: =IF('Zoopl Count'!I31=0,"",('Zoopl Analysis'!I31*LN('Zoopl Analysis'!I31))) | J31: =IF('Zoopl Count'!J31=0,"",('Zoopl Analysis'!J31*LN('Zoopl Analysis'!J31))) | K31: =IF('Zoopl Count'!K31=0,"",('Zoopl Analysis'!K31*LN('Zoopl Analysis'!K31))) | L31: =IF('Zoopl Count'!L31=0,"",('Zoopl Analysis'!L31*LN('Zoopl Analysis'!L31))) | M31: =IF('Zoopl Count'!M31=0,"",('Zoopl Analysis'!M31*LN('Zoopl Analysis'!M31))) | N31: =IF('Zoopl Count'!N31=0,"",('Zoopl Analysis'!N31*LN('Zoopl Analysis'!N31))) | ... P31: =IF('Zoopl Count'!P31=0,"",('Zoopl Analysis'!P31*LN('Zoopl Analysis'!P31)))
E32: Genus: | F32: Planularia | G32: =IF('Zoopl Count'!G32=0,"",('Zoopl Analysis'!G32*LN('Zoopl Analysis'!G32))) | H32: =IF('Zoopl Count'!H32=0,"",('Zoopl Analysis'!H32*LN('Zoopl Analysis'!H32))) | I32: =IF('Zoopl Count'!I32=0,"",('Zoopl Analysis'!I32*LN('Zoopl Analysis'!I32))) | J32: =IF('Zoopl Count'!J32=0,"",('Zoopl Analysis'!J32*LN('Zoopl Analysis'!J32))) | K32: =IF('Zoopl Count'!K32=0,"",('Zoopl Analysis'!K32*LN('Zoopl Analysis'!K32))) | L32: =IF('Zoopl Count'!L32=0,"",('Zoopl Analysis'!L32*LN('Zoopl Analysis'!L32))) | M32: =IF('Zoopl Count'!M32=0,"",('Zoopl Analysis'!M32*LN('Zoopl Analysis'!M32))) | N32: =IF('Zoopl Count'!N32=0,"",('Zoopl Analysis'!N32*LN('Zoopl Analysis'!N32))) | ... P32: =IF('Zoopl Count'!P32=0,"",('Zoopl Analysis'!P32*LN('Zoopl Analysis'!P32)))
F33: Lenticulina | G33: =IF('Zoopl Count'!G33=0,"",('Zoopl Analysis'!G33*LN('Zoopl Analysis'!G33))) | H33: =IF('Zoopl Count'!H33=0,"",('Zoopl Analysis'!H33*LN('Zoopl Analysis'!H33))) | I33: =IF('Zoopl Count'!I33=0,"",('Zoopl Analysis'!I33*LN('Zoopl Analysis'!I33))) | J33: =IF('Zoopl Count'!J33=0,"",('Zoopl Analysis'!J33*LN('Zoopl Analysis'!J33))) | K33: =IF('Zoopl Count'!K33=0,"",('Zoopl Analysis'!K33*LN('Zoopl Analysis'!K33))) | L33: =IF('Zoopl Count'!L33=0,"",('Zoopl Analysis'!L33*LN('Zoopl Analysis'!L33))) | M33: =IF('Zoopl Count'!M33=0,"",('Zoopl Analysis'!M33*LN('Zoopl Analysis'!M33))) | N33: =IF('Zoopl Count'!N33=0,"",('Zoopl Analysis'!N33*LN('Zoopl Analysis'!N33))) | ... P33: =IF('Zoopl Count'!P33=0,"",('Zoopl Analysis'!P33*LN('Zoopl Analysis'!P33)))
F34: Vaginulina | G34: =IF('Zoopl Count'!G34=0,"",('Zoopl Analysis'!G34*LN('Zoopl Analysis'!G34))) | H34: =IF('Zoopl Count'!H34=0,"",('Zoopl Analysis'!H34*LN('Zoopl Analysis'!H34))) | I34: =IF('Zoopl Count'!I34=0,"",('Zoopl Analysis'!I34*LN('Zoopl Analysis'!I34))) | J34: =IF('Zoopl Count'!J34=0,"",('Zoopl Analysis'!J34*LN('Zoopl Analysis'!J34))) | K34: =IF('Zoopl Count'!K34=0,"",('Zoopl Analysis'!K34*LN('Zoopl Analysis'!K34))) | L34: =IF('Zoopl Count'!L34=0,"",('Zoopl Analysis'!L34*LN('Zoopl Analysis'!L34))) | M34: =IF('Zoopl Count'!M34=0,"",('Zoopl Analysis'!M34*LN('Zoopl Analysis'!M34))) | N34: =IF('Zoopl Count'!N34=0,"",('Zoopl Analysis'!N34*LN('Zoopl Analysis'!N34))) | ... P34: =IF('Zoopl Count'!P34=0,"",('Zoopl Analysis'!P34*LN('Zoopl Analysis'!P34)))
G35: =IF('Zoopl Count'!G35=0,"",('Zoopl Analysis'!G35*LN('Zoopl Analysis'!G35))) | H35: =IF('Zoopl Count'!H35=0,"",('Zoopl Analysis'!H35*LN('Zoopl Analysis'!H35))) | I35: =IF('Zoopl Count'!I35=0,"",('Zoopl Analysis'!I35*LN('Zoopl Analysis'!I35))) | J35: =IF('Zoopl Count'!J35=0,"",('Zoopl Analysis'!J35*LN('Zoopl Analysis'!J35))) | K35: =IF('Zoopl Count'!K35=0,"",('Zoopl Analysis'!K35*LN('Zoopl Analysis'!K35))) | L35: =IF('Zoopl Count'!L35=0,"",('Zoopl Analysis'!L35*LN('Zoopl Analysis'!L35))) | M35: =IF('Zoopl Count'!M35=0,"",('Zoopl Analysis'!M35*LN('Zoopl Analysis'!M35))) | N35: =IF('Zoopl Count'!N35=0,"",('Zoopl Analysis'!N35*LN('Zoopl Analysis'!N35))) | ... P35: =IF('Zoopl Count'!P35=0,"",('Zoopl Analysis'!P35*LN('Zoopl Analysis'!P35)))
A36: Phylum: | B36: Radiozoa | G36: =IF('Zoopl Count'!G36=0,"",('Zoopl Analysis'!G36*LN('Zoopl Analysis'!G36))) | H36: =IF('Zoopl Count'!H36=0,"",('Zoopl Analysis'!H36*LN('Zoopl Analysis'!H36))) | I36: =IF('Zoopl Count'!I36=0,"",('Zoopl Analysis'!I36*LN('Zoopl Analysis'!I36))) | J36: =IF('Zoopl Count'!J36=0,"",('Zoopl Analysis'!J36*LN('Zoopl Analysis'!J36))) | K36: =IF('Zoopl Count'!K36=0,"",('Zoopl Analysis'!K36*LN('Zoopl Analysis'!K36))) | L36: =IF('Zoopl Count'!L36=0,"",('Zoopl Analysis'!L36*LN('Zoopl Analysis'!L36))) | M36: =IF('Zoopl Count'!M36=0,"",('Zoopl Analysis'!M36*LN('Zoopl Analysis'!M36))) | N36: =IF('Zoopl Count'!N36=0,"",('Zoopl Analysis'!N36*LN('Zoopl Analysis'!N36))) | ... P36: =IF('Zoopl Count'!P36=0,"",('Zoopl Analysis'!P36*LN('Zoopl Analysis'!P36)))
B37: Class: | C37: Acantharia | G37: =IF('Zoopl Count'!G37=0,"",('Zoopl Analysis'!G37*LN('Zoopl Analysis'!G37))) | H37: =IF('Zoopl Count'!H37=0,"",('Zoopl Analysis'!H37*LN('Zoopl Analysis'!H37))) | I37: =IF('Zoopl Count'!I37=0,"",('Zoopl Analysis'!I37*LN('Zoopl Analysis'!I37))) | J37: =IF('Zoopl Count'!J37=0,"",('Zoopl Analysis'!J37*LN('Zoopl Analysis'!J37))) | K37: =IF('Zoopl Count'!K37=0,"",('Zoopl Analysis'!K37*LN('Zoopl Analysis'!K37))) | L37: =IF('Zoopl Count'!L37=0,"",('Zoopl Analysis'!L37*LN('Zoopl Analysis'!L37))) | M37: =IF('Zoopl Count'!M37=0,"",('Zoopl Analysis'!M37*LN('Zoopl Analysis'!M37))) | N37: =IF('Zoopl Count'!N37=0,"",('Zoopl Analysis'!N37*LN('Zoopl Analysis'!N37))) | ... P37: =IF('Zoopl Count'!P37=0,"",('Zoopl Analysis'!P37*LN('Zoopl Analysis'!P37)))
C38: Order: | D38: Arthracanthida | G38: =IF('Zoopl Count'!G38=0,"",('Zoopl Analysis'!G38*LN('Zoopl Analysis'!G38))) | H38: =IF('Zoopl Count'!H38=0,"",('Zoopl Analysis'!H38*LN('Zoopl Analysis'!H38))) | I38: =IF('Zoopl Count'!I38=0,"",('Zoopl Analysis'!I38*LN('Zoopl Analysis'!I38))) | J38: =IF('Zoopl Count'!J38=0,"",('Zoopl Analysis'!J38*LN('Zoopl Analysis'!J38))) | K38: =IF('Zoopl Count'!K38=0,"",('Zoopl Analysis'!K38*LN('Zoopl Analysis'!K38))) | L38: =IF('Zoopl Count'!L38=0,"",('Zoopl Analysis'!L38*LN('Zoopl Analysis'!L38))) | M38: =IF('Zoopl Count'!M38=0,"",('Zoopl Analysis'!M38*LN('Zoopl Analysis'!M38))) | N38: =IF('Zoopl Count'!N38=0,"",('Zoopl Analysis'!N38*LN('Zoopl Analysis'!N38))) | ... P38: =IF('Zoopl Count'!P38=0,"",('Zoopl Analysis'!P38*LN('Zoopl Analysis'!P38)))
D39: Family: | E39: Acanthometridae | G39: =IF('Zoopl Count'!G39=0,"",('Zoopl Analysis'!G39*LN('Zoopl Analysis'!G39))) | H39: =IF('Zoopl Count'!H39=0,"",('Zoopl Analysis'!H39*LN('Zoopl Analysis'!H39))) | I39: =IF('Zoopl Count'!I39=0,"",('Zoopl Analysis'!I39*LN('Zoopl Analysis'!I39))) | J39: =IF('Zoopl Count'!J39=0,"",('Zoopl Analysis'!J39*LN('Zoopl Analysis'!J39))) | K39: =IF('Zoopl Count'!K39=0,"",('Zoopl Analysis'!K39*LN('Zoopl Analysis'!K39))) | L39: =IF('Zoopl Count'!L39=0,"",('Zoopl Analysis'!L39*LN('Zoopl Analysis'!L39))) | M39: =IF('Zoopl Count'!M39=0,"",('Zoopl Analysis'!M39*LN('Zoopl Analysis'!M39))) | N39: =IF('Zoopl Count'!N39=0,"",('Zoopl Analysis'!N39*LN('Zoopl Analysis'!N39))) | ... P39: =IF('Zoopl Count'!P39=0,"",('Zoopl Analysis'!P39*LN('Zoopl Analysis'!P39)))
E40: Genus: | F40: Acanthometron | G40: =IF('Zoopl Count'!G40=0,"",('Zoopl Analysis'!G40*LN('Zoopl Analysis'!G40))) | H40: =IF('Zoopl Count'!H40=0,"",('Zoopl Analysis'!H40*LN('Zoopl Analysis'!H40))) | I40: =IF('Zoopl Count'!I40=0,"",('Zoopl Analysis'!I40*LN('Zoopl Analysis'!I40))) | J40: =IF('Zoopl Count'!J40=0,"",('Zoopl Analysis'!J40*LN('Zoopl Analysis'!J40))) | K40: =IF('Zoopl Count'!K40=0,"",('Zoopl Analysis'!K40*LN('Zoopl Analysis'!K40))) | L40: =IF('Zoopl Count'!L40=0,"",('Zoopl Analysis'!L40*LN('Zoopl Analysis'!L40))) | M40: =IF('Zoopl Count'!M40=0,"",('Zoopl Analysis'!M40*LN('Zoopl Analysis'!M40))) | N40: =IF('Zoopl Count'!N40=0,"",('Zoopl Analysis'!N40*LN('Zoopl Analysis'!N40))) | ... P40: =IF('Zoopl Count'!P40=0,"",('Zoopl Analysis'!P40*LN('Zoopl Analysis'!P40)))
G41: =IF('Zoopl Count'!G41=0,"",('Zoopl Analysis'!G41*LN('Zoopl Analysis'!G41))) | H41: =IF('Zoopl Count'!H41=0,"",('Zoopl Analysis'!H41*LN('Zoopl Analysis'!H41))) | I41: =IF('Zoopl Count'!I41=0,"",('Zoopl Analysis'!I41*LN('Zoopl Analysis'!I41))) | J41: =IF('Zoopl Count'!J41=0,"",('Zoopl Analysis'!J41*LN('Zoopl Analysis'!J41))) | K41: =IF('Zoopl Count'!K41=0,"",('Zoopl Analysis'!K41*LN('Zoopl Analysis'!K41))) | L41: =IF('Zoopl Count'!L41=0,"",('Zoopl Analysis'!L41*LN('Zoopl Analysis'!L41))) | M41: =IF('Zoopl Count'!M41=0,"",('Zoopl Analysis'!M41*LN('Zoopl Analysis'!M41))) | N41: =IF('Zoopl Count'!N41=0,"",('Zoopl Analysis'!N41*LN('Zoopl Analysis'!N41))) | ... P41: =IF('Zoopl Count'!P41=0,"",('Zoopl Analysis'!P41*LN('Zoopl Analysis'!P41)))
G42: =IF('Zoopl Count'!G42=0,"",('Zoopl Analysis'!G42*LN('Zoopl Analysis'!G42))) | H42: =IF('Zoopl Count'!H42=0,"",('Zoopl Analysis'!H42*LN('Zoopl Analysis'!H42))) | I42: =IF('Zoopl Count'!I42=0,"",('Zoopl Analysis'!I42*LN('Zoopl Analysis'!I42))) | J42: =IF('Zoopl Count'!J42=0,"",('Zoopl Analysis'!J42*LN('Zoopl Analysis'!J42))) | K42: =IF('Zoopl Count'!K42=0,"",('Zoopl Analysis'!K42*LN('Zoopl Analysis'!K42))) | L42: =IF('Zoopl Count'!L42=0,"",('Zoopl Analysis'!L42*LN('Zoopl Analysis'!L42))) | M42: =IF('Zoopl Count'!M42=0,"",('Zoopl Analysis'!M42*LN('Zoopl Analysis'!M42))) | N42: =IF('Zoopl Count'!N42=0,"",('Zoopl Analysis'!N42*LN('Zoopl Analysis'!N42))) | ... P42: =IF('Zoopl Count'!P42=0,"",('Zoopl Analysis'!P42*LN('Zoopl Analysis'!P42)))
A43: Phylum: | B43: Ciliophora | G43: =IF('Zoopl Count'!G43=0,"",('Zoopl Analysis'!G43*LN('Zoopl Analysis'!G43))) | H43: =IF('Zoopl Count'!H43=0,"",('Zoopl Analysis'!H43*LN('Zoopl Analysis'!H43))) | I43: =IF('Zoopl Count'!I43=0,"",('Zoopl Analysis'!I43*LN('Zoopl Analysis'!I43))) | J43: =IF('Zoopl Count'!J43=0,"",('Zoopl Analysis'!J43*LN('Zoopl Analysis'!J43))) | K43: =IF('Zoopl Count'!K43=0,"",('Zoopl Analysis'!K43*LN('Zoopl Analysis'!K43))) | L43: =IF('Zoopl Count'!L43=0,"",('Zoopl Analysis'!L43*LN('Zoopl Analysis'!L43))) | M43: =IF('Zoopl Count'!M43=0,"",('Zoopl Analysis'!M43*LN('Zoopl Analysis'!M43))) | N43: =IF('Zoopl Count'!N43=0,"",('Zoopl Analysis'!N43*LN('Zoopl Analysis'!N43))) | ... P43: =IF('Zoopl Count'!P43=0,"",('Zoopl Analysis'!P43*LN('Zoopl Analysis'!P43)))
B44: Class: | C44: Oligotrichea | G44: =IF('Zoopl Count'!G44=0,"",('Zoopl Analysis'!G44*LN('Zoopl Analysis'!G44))) | H44: =IF('Zoopl Count'!H44=0,"",('Zoopl Analysis'!H44*LN('Zoopl Analysis'!H44))) | I44: =IF('Zoopl Count'!I44=0,"",('Zoopl Analysis'!I44*LN('Zoopl Analysis'!I44))) | J44: =IF('Zoopl Count'!J44=0,"",('Zoopl Analysis'!J44*LN('Zoopl Analysis'!J44))) | K44: =IF('Zoopl Count'!K44=0,"",('Zoopl Analysis'!K44*LN('Zoopl Analysis'!K44))) | L44: =IF('Zoopl Count'!L44=0,"",('Zoopl Analysis'!L44*LN('Zoopl Analysis'!L44))) | M44: =IF('Zoopl Count'!M44=0,"",('Zoopl Analysis'!M44*LN('Zoopl Analysis'!M44))) | N44: =IF('Zoopl Count'!N44=0,"",('Zoopl Analysis'!N44*LN('Zoopl Analysis'!N44))) | ... P44: =IF('Zoopl Count'!P44=0,"",('Zoopl Analysis'!P44*LN('Zoopl Analysis'!P44)))
C45: Order: | D45: Choreotrichida | G45: =IF('Zoopl Count'!G45=0,"",('Zoopl Analysis'!G45*LN('Zoopl Analysis'!G45))) | H45: =IF('Zoopl Count'!H45=0,"",('Zoopl Analysis'!H45*LN('Zoopl Analysis'!H45))) | I45: =IF('Zoopl Count'!I45=0,"",('Zoopl Analysis'!I45*LN('Zoopl Analysis'!I45))) | J45: =IF('Zoopl Count'!J45=0,"",('Zoopl Analysis'!J45*LN('Zoopl Analysis'!J45))) | K45: =IF('Zoopl Count'!K45=0,"",('Zoopl Analysis'!K45*LN('Zoopl Analysis'!K45))) | L45: =IF('Zoopl Count'!L45=0,"",('Zoopl Analysis'!L45*LN('Zoopl Analysis'!L45))) | M45: =IF('Zoopl Count'!M45=0,"",('Zoopl Analysis'!M45*LN('Zoopl Analysis'!M45))) | N45: =IF('Zoopl Count'!N45=0,"",('Zoopl Analysis'!N45*LN('Zoopl Analysis'!N45))) | ... P45: =IF('Zoopl Count'!P45=0,"",('Zoopl Analysis'!P45*LN('Zoopl Analysis'!P45)))
...

Sheet Sheet2
A1: Phylum: | B1: Cnidaria | J1: UniqueID | K1: Phylum | L1: Class | M1: Order | N1: Family | O1: Genus | P1: Species
F2: Anthozoa larvae | K2: Cnidaria | P2: Anthozoa larvae
F3: Planulae larvae | K3: Cnidaria | P3: Planulae larvae
B4: Class: | C4: Hydrozoa | K4: Cnidaria | L4: Hydrozoa | P4: Actinula larvae
F5: Actinula larvae | K5: Cnidaria | L5: Hydrozoa | M5: Leptothecata | N5: Campanulariidae | O5: Obelia
C6: Order: | D6: Leptothecata | K6: Cnidaria | L6: Hydrozoa | M6: Limnomedusae | N6: Geryoniidae | O6: Liriope
D7: Family: | E7: Campanulariidae | K7: Cnidaria | L7: Hydrozoa | M7: Siphonophorae
E8: Genus: | F8: Obelia | K8: Cnidaria | L8: Hydrozoa | M8: Trachymedusae | N8: Rhopalonematidae | O8: Aglaura
K9: Cnidaria | L9: Hydrozoa | M9: Trachymedusae | N9: Rhopalonematidae | O9: Aglantha
C10: Order: | D10: Limnomedusae | K10: Cnidaria | L10: Scyphozoa | P10: Ephyra larvae
D11: Family: | E11: Geryoniidae | K11: Ctenophora | P11: Other ctenophores
E12: Genus: | F12: Liriope | K12: Ctenophora | L12: Tentaculata | M12: Lobata | N12: Bolinopsidae | O12: Bolinopsis
K13: Ctenophora | L13: Tentaculata | M13: Cydippida | N13: Cydippidae | O13: Pleurobrachia
C14: Order: | D14: Siphonophorae | K14: Ctenophora | L14: Nuda | M14: Beroida | N14: Beroidae | O14: Beroe
K15: Annelida | P15: Other annelids
C16: Order: | D16: Trachymedusae | K16: Annelida | L16: Polychaeta | P16: Polychaete larvae
D17: Family: | E17: Rhopalonematidae | K17: Annelida | L17: Polychaeta | M17: Phyllodocida | N17: Tomopteridae | O17: Tomopteris
E18: Genus: | F18: Aglaura | K18: Annelida | L18: Polychaeta | M18: Terebellida | N18: Pectinariidae | O18: Pectinaria
F19: Aglantha | K19: Platyhelminthes | L19: Trematoda
K20: Nematoda | P20: Nematode
B21: Class: | C21: Scyphozoa | K21: Arthropoda | L21: Branchiopoda | P21: Other branchiopods
F22: Ephyra larvae | K22: Arthropoda | L22: Branchiopoda | M22: Onychopoda | N22: Podonidae | O22: Evadne
K23: Arthropoda | L23: Branchiopoda | M23: Onychopoda | N23: Podonidae | O23: Podon
A24: Phylum: | B24: Ctenophora | K24: Arthropoda | L24: Ostracoda | P24: Other ostracods
F25: Other ctenophores | K25: Arthropoda | L25: Ostracoda | M25: Halocyprida | N25: Halocyprididae | O25: Euconchoecia
B26: Class: | C26: Tentaculata | K26: Arthropoda | L26: Ostracoda | M26: Myodocopida | N26: Cypridinidae | O26: Cypridina
C27: Order: | D27: Lobata | K27: Arthropoda | L27: Copepoda | P27: Copepod egg sac
D28: Family: | E28: Bolinopsidae | K28: Arthropoda | L28: Copepoda | P28: Copepod nauplii
E29: Genus: | F29: Bolinopsis | K29: Arthropoda | L29: Copepoda | M29: Calanoida | P29: Calanoid copepodite
K30: Arthropoda | L30: Copepoda | M30: Calanoida | P30: Other calanoids
C31: Order: | D31: Cydippida | K31: Arthropoda | L31: Copepoda | M31: Calanoida | N31: Acartiidae | O31: Acartia
D32: Family: | E32: Cydippidae | K32: Arthropoda | L32: Copepoda | M32: Calanoida | N32: Aetideidae | O32: Aetideus
E33: Genus: | F33: Pleurobrachia | K33: Arthropoda | L33: Copepoda | M33: Calanoida | N33: Arietellidae | O33: Metacalanus
K34: Arthropoda | L34: Copepoda | M34: Calanoida | N34: Augaptilidae | O34: Haloptilus
B35: Class: | C35: Nuda | K35: Arthropoda | L35: Copepoda | M35: Calanoida | N35: Calanidae | O35: Undinula
C36: Order: | D36: Beroida | K36: Arthropoda | L36: Copepoda | M36: Calanoida | N36: Calanidae | O36: Calanus
D37: Family: | E37: Beroidae | K37: Arthropoda | L37: Copepoda | M37: Calanoida | N37: Calanidae | O37: Canthocalanus
E38: Genus: | F38: Beroe | K38: Arthropoda | L38: Copepoda | M38: Calanoida | N38: Calanidae | O38: Neocalanus
K39: Arthropoda | L39: Copepoda | M39: Calanoida | N39: Calanidae | O39: Nannocalanus
A40: Phylum: | B40: Annelida | K40: Arthropoda | L40: Copepoda | M40: Calanoida | N40: Calanidae | O40: Cosmocalanus
...

Sheet PivotTable
B3: Values
